Workbook
Name Offset: Punkte!$B$10

Sheet Rangliste
A1: Ranking | B1: Name | C1: Verein | D1: LV | E1: M/W/D | F1: SpielerID | G1: Jg. | H1: WBV 1 | I1: WBV 2 | J1: WBV 3 | K1: WBV 4 | L1: NÖBV 1 | M1: NÖBV 2 | N1: NÖBV 3 | O1: Regio 1 | P1: Regio 2 | Q1: Regio 3 | R1: LV Points | S1: Regio Points | T1: NW OST | U1: Stand: WBV: 31.06.2026 NÖBV: 5.7.2026 Regio: 15.3.2026
A2: 1 | B2: Valentin Grebien | C2: WBH WIEN | D2: WBV | E2: M | F2: 108667 | G2: 2010 | H2: =MAX(IF(ISNA(VLOOKUP(B2,'WBV 1'!$B$3:$C$34,2,FALSE))=TRUE,0,VLOOKUP(B2,'WBV 1'!$B$3:$C$34,2,FALSE)),IF(ISNA(VLOOKUP(B2,'WBV 1'!$F$3:$G$34,2,FALSE))=TRUE,0,VLOOKUP(B2,'WBV 1'!$F$3:$G$34,2,FALSE)),IF(ISNA(VLOOKUP(B2,'WBV 1'!$J$3:$K$34,2,FALSE))=TRUE,0,VLOOKUP(B2,'WBV 1'!$J$3:$K$34,2,FALSE)),IF(ISNA(VLOOKUP(B2,'WBV 1'!$N$3:$O$34,2,FALSE))=TRUE,0,VLOOKUP(B2,'WBV 1'!$N$3:$O$34,2,FALSE))) -> 0 | I2: =MAX(IF(ISNA(VLOOKUP(B2,'WBV 2'!$B$3:$C$34,2,FALSE))=TRUE,0,VLOOKUP(B2,'WBV 2'!$B$3:$C$34,2,FALSE)),IF(ISNA(VLOOKUP(B2,'WBV 2'!$F$3:$G$34,2,FALSE))=TRUE,0,VLOOKUP(B2,'WBV 2'!$F$3:$G$34,2,FALSE)),IF(ISNA(VLOOKUP(B2,'WBV 2'!$J$3:$K$34,2,FALSE))=TRUE,0,VLOOKUP(B2,'WBV 2'!$J$3:$K$34,2,FALSE)),IF(ISNA(VLOOKUP(B2,'WBV 2'!$N$3:$O$34,2,FALSE))=TRUE,0,VLOOKUP(B2,'WBV 2'!$N$3:$O$34,2,FALSE))) -> 0 | J2: =MAX(IF(ISNA(VLOOKUP(B2,'WBV 3'!$B$3:$C$34,2,FALSE))=TRUE,0,VLOOKUP(B2,'WBV 3'!$B$3:$C$34,2,FALSE)),IF(ISNA(VLOOKUP(B2,'WBV 3'!$F$3:$G$34,2,FALSE))=TRUE,0,VLOOKUP(B2,'WBV 3'!$F$3:$G$34,2,FALSE)),IF(ISNA(VLOOKUP(B2,'WBV 3'!$J$3:$K$34,2,FALSE))=TRUE,0,VLOOKUP(B2,'WBV 3'!$J$3:$K$34,2,FALSE)),IF(ISNA(VLOOKUP(B2,'WBV 3'!$N$3:$O$34,2,FALSE))=TRUE,0,VLOOKUP(B2,'WBV 3'!$N$3:$O$34,2,FALSE))) -> 0 | K2: =MAX(IF(ISNA(VLOOKUP(B2,'WBV 4'!$B$3:$C$34,2,FALSE))=TRUE,0,VLOOKUP(B2,'WBV 4'!$B$3:$C$34,2,FALSE)),IF(ISNA(VLOOKUP(B2,'WBV 4'!$F$3:$G$34,2,FALSE))=TRUE,0,VLOOKUP(B2,'WBV 4'!$F$3:$G$34,2,FALSE)),IF(ISNA(VLOOKUP(B2,'WBV 4'!$J$3:$K$34,2,FALSE))=TRUE,0,VLOOKUP(B2,'WBV 4'!$J$3:$K$34,2,FALSE)),IF(ISNA(VLOOKUP(B2,'WBV 4'!$N$3:$O$34,2,FALSE))=TRUE,0,VLOOKUP(B2,'WBV 4'!$N$3:$O$34,2,FALSE))) -> 0 | L2: =MAX(IF(ISNA(VLOOKUP(B2,'NÖBV 1'!$B$3:$C$34,2,FALSE))=TRUE,0,VLOOKUP(B2,'NÖBV 1'!$B$3:$C$34,2,FALSE)),IF(ISNA(VLOOKUP(B2,'NÖBV 1'!$F$3:$G$34,2,FALSE))=TRUE,0,VLOOKUP(B2,'NÖBV 1'!$F$3:$G$34,2,FALSE)),IF(ISNA(VLOOKUP(B2,'NÖBV 1'!$J$3:$K$34,2,FALSE))=TRUE,0,VLOOKUP(B2,'NÖBV 1'!$J$3:$K$34,2,FALSE)),IF(ISNA(VLOOKUP(B2,'NÖBV 1'!$N$3:$O$34,2,FALSE))=TRUE,0,VLOOKUP(B2,'NÖBV 1'!$N$3:$O$34,2,FALSE))) -> 0 | M2: =MAX(IF(ISNA(VLOOKUP(B2,'NÖBV 2'!$B$3:$C$34,2,FALSE))=TRUE,0,VLOOKUP(B2,'NÖBV 2'!$B$3:$C$34,2,FALSE)),IF(ISNA(VLOOKUP(B2,'NÖBV 2'!$F$3:$G$34,2,FALSE))=TRUE,0,VLOOKUP(B2,'NÖBV 2'!$F$3:$G$34,2,FALSE)),IF(ISNA(VLOOKUP(B2,'NÖBV 2'!$J$3:$K$34,2,FALSE))=TRUE,0,VLOOKUP(B2,'NÖBV 2'!$J$3:$K$34,2,FALSE)),IF(ISNA(VLOOKUP(B2,'NÖBV 2'!$N$3:$O$34,2,FALSE))=TRUE,0,VLOOKUP(B2,'NÖBV 2'!$N$3:$O$34,2,FALSE))) -> 0 | N2: =MAX(IF(ISNA(VLOOKUP(B2,'NÖBV 3'!$B$3:$C$34,2,FALSE))=TRUE,0,VLOOKUP(B2,'NÖBV 3'!$B$3:$C$34,2,FALSE)),IF(ISNA(VLOOKUP(B2,'NÖBV 3'!$F$3:$G$34,2,FALSE))=TRUE,0,VLOOKUP(B2,'NÖBV 3'!$F$3:$G$34,2,FALSE)),IF(ISNA(VLOOKUP(B2,'NÖBV 3'!$J$3:$K$34,2,FALSE))=TRUE,0,VLOOKUP(B2,'NÖBV 3'!$J$3:$K$34,2,FALSE)),IF(ISNA(VLOOKUP(B2,'NÖBV 3'!$N$3:$O$34,2,FALSE))=TRUE,0,VLOOKUP(B2,'NÖBV 3'!$N$3:$O$34,2,FALSE))) -> 0 | O2: =MAX(IF(ISNA(VLOOKUP(B2,'Regioturnier 1'!$B$3:$C$34,2,FALSE))=TRUE,0,VLOOKUP(B2,'Regioturnier 1'!$B$3:$C$34,2,FALSE)),IF(ISNA(VLOOKUP(B2,'Regioturnier 1'!$F$3:$G$34,2,FALSE))=TRUE,0,VLOOKUP(B2,'Regioturnier 1'!$F$3:$G$34,2,FALSE)),IF(ISNA(VLOOKUP(B2,'Regioturnier 1'!$J$3:$K$34,2,FALSE))=TRUE,0,VLOOKUP(B2,'Regioturnier 1'!$J$3:$K$34,2,FALSE)),IF(ISNA(VLOOKUP(B2,'Regioturnier 1'!$N$3:$O$34,2,FALSE))=TRUE,0,VLOOKUP(B2,'Regioturnier 1'!$N$3:$O$34,2,FALSE)),IF(ISNA(VLOOKUP(B2,'Regioturnier 1'!$R$3:$S$34,2,FALSE))=TRUE,0,VLOOKUP(B2,'Regioturnier 1'!$R$3:$S$34,2,FALSE)), IF(ISNA(VLOOKUP(B2,'Regioturnier 1'!$V$3:$W$34,2,FALSE))=TRUE,0,VLOOKUP(B2,'Regioturnier 1'!$V$3:$W$34,2,FALSE)), IF(ISNA(VLOOKUP(B2,'Regioturnier 1'!$Z$3:$AA$34,2,FALSE))=TRUE,0,VLOOKUP(B2,'Regioturnier 1'!$Z$3:$AA$34,2,FALSE))) -> 216 | P2: =MAX(IF(ISNA(VLOOKUP(B2,'Regioturnier 2'!$B$3:$C$34,2,FALSE))=TRUE,0,VLOOKUP(B2,'Regioturnier 2'!$B$3:$C$34,2,FALSE)),IF(ISNA(VLOOKUP(B2,'Regioturnier 2'!$F$3:$G$34,2,FALSE))=TRUE,0,VLOOKUP(B2,'Regioturnier 2'!$F$3:$G$34,2,FALSE)),IF(ISNA(VLOOKUP(B2,'Regioturnier 2'!$J$3:$K$34,2,FALSE))=TRUE,0,VLOOKUP(B2,'Regioturnier 2'!$J$3:$K$34,2,FALSE)),IF(ISNA(VLOOKUP(B2,'Regioturnier 2'!$N$3:$O$34,2,FALSE))=TRUE,0,VLOOKUP(B2,'Regioturnier 2'!$N$3:$O$34,2,FALSE)),IF(ISNA(VLOOKUP(B2,'Regioturnier 2'!$R$3:$S$34,2,FALSE))=TRUE,0,VLOOKUP(B2,'Regioturnier 2'!$R$3:$S$34,2,FALSE)), IF(ISNA(VLOOKUP(B2,'Regioturnier 2'!$V$3:$W$34,2,FALSE))=TRUE,0,VLOOKUP(B2,'Regioturnier 2'!$V$3:$W$34,2,FALSE)), IF(ISNA(VLOOKUP(B2,'Regioturnier 2'!$Z$3:$AA$34,2,FALSE))=TRUE,0,VLOOKUP(B2,'Regioturnier 2'!$Z$3:$AA$34,2,FALSE))) -> 220 | Q2: =MAX(IF(ISNA(VLOOKUP(B2,'Regioturnier 3'!$B$3:$C$34,2,FALSE))=TRUE,0,VLOOKUP(B2,'Regioturnier 3'!$B$3:$C$34,2,FALSE)),IF(ISNA(VLOOKUP(B2,'Regioturnier 3'!$F$3:$G$34,2,FALSE))=TRUE,0,VLOOKUP(B2,'Regioturnier 3'!$F$3:$G$34,2,FALSE)),IF(ISNA(VLOOKUP(B2,'Regioturnier 3'!$J$3:$K$34,2,FALSE))=TRUE,0,VLOOKUP(B2,'Regioturnier 3'!$J$3:$K$34,2,FALSE)),IF(ISNA(VLOOKUP(B2,'Regioturnier 3'!$N$3:$O$34,2,FALSE))=TRUE,0,VLOOKUP(B2,'Regioturnier 3'!$N$3:$O$34,2,FALSE)),IF(ISNA(VLOOKUP(B2,'Regioturnier 3'!$R$3:$S$34,2,FALSE))=TRUE,0,VLOOKUP(B2,'Regioturnier 3'!$R$3:$S$34,2,FALSE)), IF(ISNA(VLOOKUP(B2,'Regioturnier 3'!$V$3:$W$34,2,FALSE))=TRUE,0,VLOOKUP(B2,'Regioturnier 3'!$V$3:$W$34,2,FALSE)), IF(ISNA(VLOOKUP(B2,'Regioturnier 3'!$Z$3:$AA$34,2,FALSE))=TRUE,0,VLOOKUP(B2,'Regioturnier 3'!$Z$3:$AA$34,2,FALSE))) -> 0 | R2: =0.5*INDEX($H2:$N2,MATCH(LARGE($H2:$N2,1),$H2:$N2,0))+0.3*INDEX($H2:$N2,MATCH(LARGE($H2:$N2,2),$H2:$N2,0))+0.2*INDEX($H2:$N2,MATCH(LARGE($H2:$N2,3),$H2:$N2,0)) -> 0 | S2: =0.6*INDEX(O2:Q2,MATCH(LARGE(O2:Q2,1),O2:Q2,0))+0.4*INDEX(O2:Q2,MATCH(LARGE(O2:Q2,2),O2:Q2,0))+0*INDEX(O2:Q2,MATCH(LARGE(O2:Q2,3),O2:Q2,0)) -> 218.4 | T2: =1*INDEX(R2:S2,MATCH(LARGE(R2:S2,1),R2:S2,0))+0*INDEX(R2:S2,MATCH(LARGE(R2:S2,2),R2:S2,0)) -> 218.4
A3: 2 | B3: Xinjie Chen | C3: WBH WIEN | D3: WBV | E3: M | F3: 111768 | G3: 2011 | H3: =MAX(IF(ISNA(VLOOKUP(B3,'WBV 1'!$B$3:$C$34,2,FALSE))=TRUE,0,VLOOKUP(B3,'WBV 1'!$B$3:$C$34,2,FALSE)),IF(ISNA(VLOOKUP(B3,'WBV 1'!$F$3:$G$34,2,FALSE))=TRUE,0,VLOOKUP(B3,'WBV 1'!$F$3:$G$34,2,FALSE)),IF(ISNA(VLOOKUP(B3,'WBV 1'!$J$3:$K$34,2,FALSE))=TRUE,0,VLOOKUP(B3,'WBV 1'!$J$3:$K$34,2,FALSE)),IF(ISNA(VLOOKUP(B3,'WBV 1'!$N$3:$O$34,2,FALSE))=TRUE,0,VLOOKUP(B3,'WBV 1'!$N$3:$O$34,2,FALSE))) -> 194 | I3: =MAX(IF(ISNA(VLOOKUP(B3,'WBV 2'!$B$3:$C$34,2,FALSE))=TRUE,0,VLOOKUP(B3,'WBV 2'!$B$3:$C$34,2,FALSE)),IF(ISNA(VLOOKUP(B3,'WBV 2'!$F$3:$G$34,2,FALSE))=TRUE,0,VLOOKUP(B3,'WBV 2'!$F$3:$G$34,2,FALSE)),IF(ISNA(VLOOKUP(B3,'WBV 2'!$J$3:$K$34,2,FALSE))=TRUE,0,VLOOKUP(B3,'WBV 2'!$J$3:$K$34,2,FALSE)),IF(ISNA(VLOOKUP(B3,'WBV 2'!$N$3:$O$34,2,FALSE))=TRUE,0,VLOOKUP(B3,'WBV 2'!$N$3:$O$34,2,FALSE))) -> 200 | J3: =MAX(IF(ISNA(VLOOKUP(B3,'WBV 3'!$B$3:$C$34,2,FALSE))=TRUE,0,VLOOKUP(B3,'WBV 3'!$B$3:$C$34,2,FALSE)),IF(ISNA(VLOOKUP(B3,'WBV 3'!$F$3:$G$34,2,FALSE))=TRUE,0,VLOOKUP(B3,'WBV 3'!$F$3:$G$34,2,FALSE)),IF(ISNA(VLOOKUP(B3,'WBV 3'!$J$3:$K$34,2,FALSE))=TRUE,0,VLOOKUP(B3,'WBV 3'!$J$3:$K$34,2,FALSE)),IF(ISNA(VLOOKUP(B3,'WBV 3'!$N$3:$O$34,2,FALSE))=TRUE,0,VLOOKUP(B3,'WBV 3'!$N$3:$O$34,2,FALSE))) -> 0 | K3: =MAX(IF(ISNA(VLOOKUP(B3,'WBV 4'!$B$3:$C$34,2,FALSE))=TRUE,0,VLOOKUP(B3,'WBV 4'!$B$3:$C$34,2,FALSE)),IF(ISNA(VLOOKUP(B3,'WBV 4'!$F$3:$G$34,2,FALSE))=TRUE,0,VLOOKUP(B3,'WBV 4'!$F$3:$G$34,2,FALSE)),IF(ISNA(VLOOKUP(B3,'WBV 4'!$J$3:$K$34,2,FALSE))=TRUE,0,VLOOKUP(B3,'WBV 4'!$J$3:$K$34,2,FALSE)),IF(ISNA(VLOOKUP(B3,'WBV 4'!$N$3:$O$34,2,FALSE))=TRUE,0,VLOOKUP(B3,'WBV 4'!$N$3:$O$34,2,FALSE))) -> 0 | L3: =MAX(IF(ISNA(VLOOKUP(B3,'NÖBV 1'!$B$3:$C$34,2,FALSE))=TRUE,0,VLOOKUP(B3,'NÖBV 1'!$B$3:$C$34,2,FALSE)),IF(ISNA(VLOOKUP(B3,'NÖBV 1'!$F$3:$G$34,2,FALSE))=TRUE,0,VLOOKUP(B3,'NÖBV 1'!$F$3:$G$34,2,FALSE)),IF(ISNA(VLOOKUP(B3,'NÖBV 1'!$J$3:$K$34,2,FALSE))=TRUE,0,VLOOKUP(B3,'NÖBV 1'!$J$3:$K$34,2,FALSE)),IF(ISNA(VLOOKUP(B3,'NÖBV 1'!$N$3:$O$34,2,FALSE))=TRUE,0,VLOOKUP(B3,'NÖBV 1'!$N$3:$O$34,2,FALSE))) -> 0 | M3: =MAX(IF(ISNA(VLOOKUP(B3,'NÖBV 2'!$B$3:$C$34,2,FALSE))=TRUE,0,VLOOKUP(B3,'NÖBV 2'!$B$3:$C$34,2,FALSE)),IF(ISNA(VLOOKUP(B3,'NÖBV 2'!$F$3:$G$34,2,FALSE))=TRUE,0,VLOOKUP(B3,'NÖBV 2'!$F$3:$G$34,2,FALSE)),IF(ISNA(VLOOKUP(B3,'NÖBV 2'!$J$3:$K$34,2,FALSE))=TRUE,0,VLOOKUP(B3,'NÖBV 2'!$J$3:$K$34,2,FALSE)),IF(ISNA(VLOOKUP(B3,'NÖBV 2'!$N$3:$O$34,2,FALSE))=TRUE,0,VLOOKUP(B3,'NÖBV 2'!$N$3:$O$34,2,FALSE))) -> 0 | N3: =MAX(IF(ISNA(VLOOKUP(B3,'NÖBV 3'!$B$3:$C$34,2,FALSE))=TRUE,0,VLOOKUP(B3,'NÖBV 3'!$B$3:$C$34,2,FALSE)),IF(ISNA(VLOOKUP(B3,'NÖBV 3'!$F$3:$G$34,2,FALSE))=TRUE,0,VLOOKUP(B3,'NÖBV 3'!$F$3:$G$34,2,FALSE)),IF(ISNA(VLOOKUP(B3,'NÖBV 3'!$J$3:$K$34,2,FALSE))=TRUE,0,VLOOKUP(B3,'NÖBV 3'!$J$3:$K$34,2,FALSE)),IF(ISNA(VLOOKUP(B3,'NÖBV 3'!$N$3:$O$34,2,FALSE))=TRUE,0,VLOOKUP(B3,'NÖBV 3'!$N$3:$O$34,2,FALSE))) -> 0 | O3: =MAX(IF(ISNA(VLOOKUP(B3,'Regioturnier 1'!$B$3:$C$34,2,FALSE))=TRUE,0,VLOOKUP(B3,'Regioturnier 1'!$B$3:$C$34,2,FALSE)),IF(ISNA(VLOOKUP(B3,'Regioturnier 1'!$F$3:$G$34,2,FALSE))=TRUE,0,VLOOKUP(B3,'Regioturnier 1'!$F$3:$G$34,2,FALSE)),IF(ISNA(VLOOKUP(B3,'Regioturnier 1'!$J$3:$K$34,2,FALSE))=TRUE,0,VLOOKUP(B3,'Regioturnier 1'!$J$3:$K$34,2,FALSE)),IF(ISNA(VLOOKUP(B3,'Regioturnier 1'!$N$3:$O$34,2,FALSE))=TRUE,0,VLOOKUP(B3,'Regioturnier 1'!$N$3:$O$34,2,FALSE)),IF(ISNA(VLOOKUP(B3,'Regioturnier 1'!$R$3:$S$34,2,FALSE))=TRUE,0,VLOOKUP(B3,'Regioturnier 1'!$R$3:$S$34,2,FALSE)), IF(ISNA(VLOOKUP(B3,'Regioturnier 1'!$V$3:$W$34,2,FALSE))=TRUE,0,VLOOKUP(B3,'Regioturnier 1'!$V$3:$W$34,2,FALSE)), IF(ISNA(VLOOKUP(B3,'Regioturnier 1'!$Z$3:$AA$34,2,FALSE))=TRUE,0,VLOOKUP(B3,'Regioturnier 1'!$Z$3:$AA$34,2,FALSE))) -> 212 | P3: =MAX(IF(ISNA(VLOOKUP(B3,'Regioturnier 2'!$B$3:$C$34,2,FALSE))=TRUE,0,VLOOKUP(B3,'Regioturnier 2'!$B$3:$C$34,2,FALSE)),IF(ISNA(VLOOKUP(B3,'Regioturnier 2'!$F$3:$G$34,2,FALSE))=TRUE,0,VLOOKUP(B3,'Regioturnier 2'!$F$3:$G$34,2,FALSE)),IF(ISNA(VLOOKUP(B3,'Regioturnier 2'!$J$3:$K$34,2,FALSE))=TRUE,0,VLOOKUP(B3,'Regioturnier 2'!$J$3:$K$34,2,FALSE)),IF(ISNA(VLOOKUP(B3,'Regioturnier 2'!$N$3:$O$34,2,FALSE))=TRUE,0,VLOOKUP(B3,'Regioturnier 2'!$N$3:$O$34,2,FALSE)),IF(ISNA(VLOOKUP(B3,'Regioturnier 2'!$R$3:$S$34,2,FALSE))=TRUE,0,VLOOKUP(B3,'Regioturnier 2'!$R$3:$S$34,2,FALSE)), IF(ISNA(VLOOKUP(B3,'Regioturnier 2'!$V$3:$W$34,2,FALSE))=TRUE,0,VLOOKUP(B3,'Regioturnier 2'!$V$3:$W$34,2,FALSE)), IF(ISNA(VLOOKUP(B3,'Regioturnier 2'!$Z$3:$AA$34,2,FALSE))=TRUE,0,VLOOKUP(B3,'Regioturnier 2'!$Z$3:$AA$34,2,FALSE))) -> 216 | Q3: =MAX(IF(ISNA(VLOOKUP(B3,'Regioturnier 3'!$B$3:$C$34,2,FALSE))=TRUE,0,VLOOKUP(B3,'Regioturnier 3'!$B$3:$C$34,2,FALSE)),IF(ISNA(VLOOKUP(B3,'Regioturnier 3'!$F$3:$G$34,2,FALSE))=TRUE,0,VLOOKUP(B3,'Regioturnier 3'!$F$3:$G$34,2,FALSE)),IF(ISNA(VLOOKUP(B3,'Regioturnier 3'!$J$3:$K$34,2,FALSE))=TRUE,0,VLOOKUP(B3,'Regioturnier 3'!$J$3:$K$34,2,FALSE)),IF(ISNA(VLOOKUP(B3,'Regioturnier 3'!$N$3:$O$34,2,FALSE))=TRUE,0,VLOOKUP(B3,'Regioturnier 3'!$N$3:$O$34,2,FALSE)),IF(ISNA(VLOOKUP(B3,'Regioturnier 3'!$R$3:$S$34,2,FALSE))=TRUE,0,VLOOKUP(B3,'Regioturnier 3'!$R$3:$S$34,2,FALSE)), IF(ISNA(VLOOKUP(B3,'Regioturnier 3'!$V$3:$W$34,2,FALSE))=TRUE,0,VLOOKUP(B3,'Regioturnier 3'!$V$3:$W$34,2,FALSE)), IF(ISNA(VLOOKUP(B3,'Regioturnier 3'!$Z$3:$AA$34,2,FALSE))=TRUE,0,VLOOKUP(B3,'Regioturnier 3'!$Z$3:$AA$34,2,FALSE))) -> 0 | R3: =0.5*INDEX($H3:$N3,MATCH(LARGE($H3:$N3,1),$H3:$N3,0))+0.3*INDEX($H3:$N3,MATCH(LARGE($H3:$N3,2),$H3:$N3,0))+0.2*INDEX($H3:$N3,MATCH(LARGE($H3:$N3,3),$H3:$N3,0)) -> 158.2 | S3: =0.6*INDEX(O3:Q3,MATCH(LARGE(O3:Q3,1),O3:Q3,0))+0.4*INDEX(O3:Q3,MATCH(LARGE(O3:Q3,2),O3:Q3,0))+0*INDEX(O3:Q3,MATCH(LARGE(O3:Q3,3),O3:Q3,0)) -> 214.4 | T3: =1*INDEX(R3:S3,MATCH(LARGE(R3:S3,1),R3:S3,0))+0*INDEX(R3:S3,MATCH(LARGE(R3:S3,2),R3:S3,0)) -> 214.4
A4: 3 | B4: Leon Lu | C4: VRC | D4: WBV | E4: M | F4: 109049 | G4: 2010 | H4: =MAX(IF(ISNA(VLOOKUP(B4,'WBV 1'!$B$3:$C$34,2,FALSE))=TRUE,0,VLOOKUP(B4,'WBV 1'!$B$3:$C$34,2,FALSE)),IF(ISNA(VLOOKUP(B4,'WBV 1'!$F$3:$G$34,2,FALSE))=TRUE,0,VLOOKUP(B4,'WBV 1'!$F$3:$G$34,2,FALSE)),IF(ISNA(VLOOKUP(B4,'WBV 1'!$J$3:$K$34,2,FALSE))=TRUE,0,VLOOKUP(B4,'WBV 1'!$J$3:$K$34,2,FALSE)),IF(ISNA(VLOOKUP(B4,'WBV 1'!$N$3:$O$34,2,FALSE))=TRUE,0,VLOOKUP(B4,'WBV 1'!$N$3:$O$34,2,FALSE))) -> 0 | I4: =MAX(IF(ISNA(VLOOKUP(B4,'WBV 2'!$B$3:$C$34,2,FALSE))=TRUE,0,VLOOKUP(B4,'WBV 2'!$B$3:$C$34,2,FALSE)),IF(ISNA(VLOOKUP(B4,'WBV 2'!$F$3:$G$34,2,FALSE))=TRUE,0,VLOOKUP(B4,'WBV 2'!$F$3:$G$34,2,FALSE)),IF(ISNA(VLOOKUP(B4,'WBV 2'!$J$3:$K$34,2,FALSE))=TRUE,0,VLOOKUP(B4,'WBV 2'!$J$3:$K$34,2,FALSE)),IF(ISNA(VLOOKUP(B4,'WBV 2'!$N$3:$O$34,2,FALSE))=TRUE,0,VLOOKUP(B4,'WBV 2'!$N$3:$O$34,2,FALSE))) -> 0 | J4: =MAX(IF(ISNA(VLOOKUP(B4,'WBV 3'!$B$3:$C$34,2,FALSE))=TRUE,0,VLOOKUP(B4,'WBV 3'!$B$3:$C$34,2,FALSE)),IF(ISNA(VLOOKUP(B4,'WBV 3'!$F$3:$G$34,2,FALSE))=TRUE,0,VLOOKUP(B4,'WBV 3'!$F$3:$G$34,2,FALSE)),IF(ISNA(VLOOKUP(B4,'WBV 3'!$J$3:$K$34,2,FALSE))=TRUE,0,VLOOKUP(B4,'WBV 3'!$J$3:$K$34,2,FALSE)),IF(ISNA(VLOOKUP(B4,'WBV 3'!$N$3:$O$34,2,FALSE))=TRUE,0,VLOOKUP(B4,'WBV 3'!$N$3:$O$34,2,FALSE))) -> 0 | K4: =MAX(IF(ISNA(VLOOKUP(B4,'WBV 4'!$B$3:$C$34,2,FALSE))=TRUE,0,VLOOKUP(B4,'WBV 4'!$B$3:$C$34,2,FALSE)),IF(ISNA(VLOOKUP(B4,'WBV 4'!$F$3:$G$34,2,FALSE))=TRUE,0,VLOOKUP(B4,'WBV 4'!$F$3:$G$34,2,FALSE)),IF(ISNA(VLOOKUP(B4,'WBV 4'!$J$3:$K$34,2,FALSE))=TRUE,0,VLOOKUP(B4,'WBV 4'!$J$3:$K$34,2,FALSE)),IF(ISNA(VLOOKUP(B4,'WBV 4'!$N$3:$O$34,2,FALSE))=TRUE,0,VLOOKUP(B4,'WBV 4'!$N$3:$O$34,2,FALSE))) -> 0 | L4: =MAX(IF(ISNA(VLOOKUP(B4,'NÖBV 1'!$B$3:$C$34,2,FALSE))=TRUE,0,VLOOKUP(B4,'NÖBV 1'!$B$3:$C$34,2,FALSE)),IF(ISNA(VLOOKUP(B4,'NÖBV 1'!$F$3:$G$34,2,FALSE))=TRUE,0,VLOOKUP(B4,'NÖBV 1'!$F$3:$G$34,2,FALSE)),IF(ISNA(VLOOKUP(B4,'NÖBV 1'!$J$3:$K$34,2,FALSE))=TRUE,0,VLOOKUP(B4,'NÖBV 1'!$J$3:$K$34,2,FALSE)),IF(ISNA(VLOOKUP(B4,'NÖBV 1'!$N$3:$O$34,2,FALSE))=TRUE,0,VLOOKUP(B4,'NÖBV 1'!$N$3:$O$34,2,FALSE))) -> 0 | M4: =MAX(IF(ISNA(VLOOKUP(B4,'NÖBV 2'!$B$3:$C$34,2,FALSE))=TRUE,0,VLOOKUP(B4,'NÖBV 2'!$B$3:$C$34,2,FALSE)),IF(ISNA(VLOOKUP(B4,'NÖBV 2'!$F$3:$G$34,2,FALSE))=TRUE,0,VLOOKUP(B4,'NÖBV 2'!$F$3:$G$34,2,FALSE)),IF(ISNA(VLOOKUP(B4,'NÖBV 2'!$J$3:$K$34,2,FALSE))=TRUE,0,VLOOKUP(B4,'NÖBV 2'!$J$3:$K$34,2,FALSE)),IF(ISNA(VLOOKUP(B4,'NÖBV 2'!$N$3:$O$34,2,FALSE))=TRUE,0,VLOOKUP(B4,'NÖBV 2'!$N$3:$O$34,2,FALSE))) -> 0 | N4: =MAX(IF(ISNA(VLOOKUP(B4,'NÖBV 3'!$B$3:$C$34,2,FALSE))=TRUE,0,VLOOKUP(B4,'NÖBV 3'!$B$3:$C$34,2,FALSE)),IF(ISNA(VLOOKUP(B4,'NÖBV 3'!$F$3:$G$34,2,FALSE))=TRUE,0,VLOOKUP(B4,'NÖBV 3'!$F$3:$G$34,2,FALSE)),IF(ISNA(VLOOKUP(B4,'NÖBV 3'!$J$3:$K$34,2,FALSE))=TRUE,0,VLOOKUP(B4,'NÖBV 3'!$J$3:$K$34,2,FALSE)),IF(ISNA(VLOOKUP(B4,'NÖBV 3'!$N$3:$O$34,2,FALSE))=TRUE,0,VLOOKUP(B4,'NÖBV 3'!$N$3:$O$34,2,FALSE))) -> 0 | O4: =MAX(IF(ISNA(VLOOKUP(B4,'Regioturnier 1'!$B$3:$C$34,2,FALSE))=TRUE,0,VLOOKUP(B4,'Regioturnier 1'!$B$3:$C$34,2,FALSE)),IF(ISNA(VLOOKUP(B4,'Regioturnier 1'!$F$3:$G$34,2,FALSE))=TRUE,0,VLOOKUP(B4,'Regioturnier 1'!$F$3:$G$34,2,FALSE)),IF(ISNA(VLOOKUP(B4,'Regioturnier 1'!$J$3:$K$34,2,FALSE))=TRUE,0,VLOOKUP(B4,'Regioturnier 1'!$J$3:$K$34,2,FALSE)),IF(ISNA(VLOOKUP(B4,'Regioturnier 1'!$N$3:$O$34,2,FALSE))=TRUE,0,VLOOKUP(B4,'Regioturnier 1'!$N$3:$O$34,2,FALSE)),IF(ISNA(VLOOKUP(B4,'Regioturnier 1'!$R$3:$S$34,2,FALSE))=TRUE,0,VLOOKUP(B4,'Regioturnier 1'!$R$3:$S$34,2,FALSE)), IF(ISNA(VLOOKUP(B4,'Regioturnier 1'!$V$3:$W$34,2,FALSE))=TRUE,0,VLOOKUP(B4,'Regioturnier 1'!$V$3:$W$34,2,FALSE)), IF(ISNA(VLOOKUP(B4,'Regioturnier 1'!$Z$3:$AA$34,2,FALSE))=TRUE,0,VLOOKUP(B4,'Regioturnier 1'!$Z$3:$AA$34,2,FALSE))) -> 214 | P4: =MAX(IF(ISNA(VLOOKUP(B4,'Regioturnier 2'!$B$3:$C$34,2,FALSE))=TRUE,0,VLOOKUP(B4,'Regioturnier 2'!$B$3:$C$34,2,FALSE)),IF(ISNA(VLOOKUP(B4,'Regioturnier 2'!$F$3:$G$34,2,FALSE))=TRUE,0,VLOOKUP(B4,'Regioturnier 2'!$F$3:$G$34,2,FALSE)),IF(ISNA(VLOOKUP(B4,'Regioturnier 2'!$J$3:$K$34,2,FALSE))=TRUE,0,VLOOKUP(B4,'Regioturnier 2'!$J$3:$K$34,2,FALSE)),IF(ISNA(VLOOKUP(B4,'Regioturnier 2'!$N$3:$O$34,2,FALSE))=TRUE,0,VLOOKUP(B4,'Regioturnier 2'!$N$3:$O$34,2,FALSE)),IF(ISNA(VLOOKUP(B4,'Regioturnier 2'!$R$3:$S$34,2,FALSE))=TRUE,0,VLOOKUP(B4,'Regioturnier 2'!$R$3:$S$34,2,FALSE)), IF(ISNA(VLOOKUP(B4,'Regioturnier 2'!$V$3:$W$34,2,FALSE))=TRUE,0,VLOOKUP(B4,'Regioturnier 2'!$V$3:$W$34,2,FALSE)), IF(ISNA(VLOOKUP(B4,'Regioturnier 2'!$Z$3:$AA$34,2,FALSE))=TRUE,0,VLOOKUP(B4,'Regioturnier 2'!$Z$3:$AA$34,2,FALSE))) -> 212 | Q4: =MAX(IF(ISNA(VLOOKUP(B4,'Regioturnier 3'!$B$3:$C$34,2,FALSE))=TRUE,0,VLOOKUP(B4,'Regioturnier 3'!$B$3:$C$34,2,FALSE)),IF(ISNA(VLOOKUP(B4,'Regioturnier 3'!$F$3:$G$34,2,FALSE))=TRUE,0,VLOOKUP(B4,'Regioturnier 3'!$F$3:$G$34,2,FALSE)),IF(ISNA(VLOOKUP(B4,'Regioturnier 3'!$J$3:$K$34,2,FALSE))=TRUE,0,VLOOKUP(B4,'Regioturnier 3'!$J$3:$K$34,2,FALSE)),IF(ISNA(VLOOKUP(B4,'Regioturnier 3'!$N$3:$O$34,2,FALSE))=TRUE,0,VLOOKUP(B4,'Regioturnier 3'!$N$3:$O$34,2,FALSE)),IF(ISNA(VLOOKUP(B4,'Regioturnier 3'!$R$3:$S$34,2,FALSE))=TRUE,0,VLOOKUP(B4,'Regioturnier 3'!$R$3:$S$34,2,FALSE)), IF(ISNA(VLOOKUP(B4,'Regioturnier 3'!$V$3:$W$34,2,FALSE))=TRUE,0,VLOOKUP(B4,'Regioturnier 3'!$V$3:$W$34,2,FALSE)), IF(ISNA(VLOOKUP(B4,'Regioturnier 3'!$Z$3:$AA$34,2,FALSE))=TRUE,0,VLOOKUP(B4,'Regioturnier 3'!$Z$3:$AA$34,2,FALSE))) -> 0 | R4: =0.5*INDEX($H4:$N4,MATCH(LARGE($H4:$N4,1),$H4:$N4,0))+0.3*INDEX($H4:$N4,MATCH(LARGE($H4:$N4,2),$H4:$N4,0))+0.2*INDEX($H4:$N4,MATCH(LARGE($H4:$N4,3),$H4:$N4,0)) -> 0 | S4: =0.6*INDEX(O4:Q4,MATCH(LARGE(O4:Q4,1),O4:Q4,0))+0.4*INDEX(O4:Q4,MATCH(LARGE(O4:Q4,2),O4:Q4,0))+0*INDEX(O4:Q4,MATCH(LARGE(O4:Q4,3),O4:Q4,0)) -> 213.2 | T4: =1*INDEX(R4:S4,MATCH(LARGE(R4:S4,1),R4:S4,0))+0*INDEX(R4:S4,MATCH(LARGE(R4:S4,2),R4:S4,0)) -> 213.2
A5: 4 | B5: Sebastian Dollinger | C5: WBH WIEN | D5: WBV | E5: M | F5: 111767 | G5: 2012 | H5: =MAX(IF(ISNA(VLOOKUP(B5,'WBV 1'!$B$3:$C$34,2,FALSE))=TRUE,0,VLOOKUP(B5,'WBV 1'!$B$3:$C$34,2,FALSE)),IF(ISNA(VLOOKUP(B5,'WBV 1'!$F$3:$G$34,2,FALSE))=TRUE,0,VLOOKUP(B5,'WBV 1'!$F$3:$G$34,2,FALSE)),IF(ISNA(VLOOKUP(B5,'WBV 1'!$J$3:$K$34,2,FALSE))=TRUE,0,VLOOKUP(B5,'WBV 1'!$J$3:$K$34,2,FALSE)),IF(ISNA(VLOOKUP(B5,'WBV 1'!$N$3:$O$34,2,FALSE))=TRUE,0,VLOOKUP(B5,'WBV 1'!$N$3:$O$34,2,FALSE))) -> 191 | I5: =MAX(IF(ISNA(VLOOKUP(B5,'WBV 2'!$B$3:$C$34,2,FALSE))=TRUE,0,VLOOKUP(B5,'WBV 2'!$B$3:$C$34,2,FALSE)),IF(ISNA(VLOOKUP(B5,'WBV 2'!$F$3:$G$34,2,FALSE))=TRUE,0,VLOOKUP(B5,'WBV 2'!$F$3:$G$34,2,FALSE)),IF(ISNA(VLOOKUP(B5,'WBV 2'!$J$3:$K$34,2,FALSE))=TRUE,0,VLOOKUP(B5,'WBV 2'!$J$3:$K$34,2,FALSE)),IF(ISNA(VLOOKUP(B5,'WBV 2'!$N$3:$O$34,2,FALSE))=TRUE,0,VLOOKUP(B5,'WBV 2'!$N$3:$O$34,2,FALSE))) -> 198 | J5: =MAX(IF(ISNA(VLOOKUP(B5,'WBV 3'!$B$3:$C$34,2,FALSE))=TRUE,0,VLOOKUP(B5,'WBV 3'!$B$3:$C$34,2,FALSE)),IF(ISNA(VLOOKUP(B5,'WBV 3'!$F$3:$G$34,2,FALSE))=TRUE,0,VLOOKUP(B5,'WBV 3'!$F$3:$G$34,2,FALSE)),IF(ISNA(VLOOKUP(B5,'WBV 3'!$J$3:$K$34,2,FALSE))=TRUE,0,VLOOKUP(B5,'WBV 3'!$J$3:$K$34,2,FALSE)),IF(ISNA(VLOOKUP(B5,'WBV 3'!$N$3:$O$34,2,FALSE))=TRUE,0,VLOOKUP(B5,'WBV 3'!$N$3:$O$34,2,FALSE))) -> 200 | K5: =MAX(IF(ISNA(VLOOKUP(B5,'WBV 4'!$B$3:$C$34,2,FALSE))=TRUE,0,VLOOKUP(B5,'WBV 4'!$B$3:$C$34,2,FALSE)),IF(ISNA(VLOOKUP(B5,'WBV 4'!$F$3:$G$34,2,FALSE))=TRUE,0,VLOOKUP(B5,'WBV 4'!$F$3:$G$34,2,FALSE)),IF(ISNA(VLOOKUP(B5,'WBV 4'!$J$3:$K$34,2,FALSE))=TRUE,0,VLOOKUP(B5,'WBV 4'!$J$3:$K$34,2,FALSE)),IF(ISNA(VLOOKUP(B5,'WBV 4'!$N$3:$O$34,2,FALSE))=TRUE,0,VLOOKUP(B5,'WBV 4'!$N$3:$O$34,2,FALSE))) -> 0 | L5: =MAX(IF(ISNA(VLOOKUP(B5,'NÖBV 1'!$B$3:$C$34,2,FALSE))=TRUE,0,VLOOKUP(B5,'NÖBV 1'!$B$3:$C$34,2,FALSE)),IF(ISNA(VLOOKUP(B5,'NÖBV 1'!$F$3:$G$34,2,FALSE))=TRUE,0,VLOOKUP(B5,'NÖBV 1'!$F$3:$G$34,2,FALSE)),IF(ISNA(VLOOKUP(B5,'NÖBV 1'!$J$3:$K$34,2,FALSE))=TRUE,0,VLOOKUP(B5,'NÖBV 1'!$J$3:$K$34,2,FALSE)),IF(ISNA(VLOOKUP(B5,'NÖBV 1'!$N$3:$O$34,2,FALSE))=TRUE,0,VLOOKUP(B5,'NÖBV 1'!$N$3:$O$34,2,FALSE))) -> 0 | M5: =MAX(IF(ISNA(VLOOKUP(B5,'NÖBV 2'!$B$3:$C$34,2,FALSE))=TRUE,0,VLOOKUP(B5,'NÖBV 2'!$B$3:$C$34,2,FALSE)),IF(ISNA(VLOOKUP(B5,'NÖBV 2'!$F$3:$G$34,2,FALSE))=TRUE,0,VLOOKUP(B5,'NÖBV 2'!$F$3:$G$34,2,FALSE)),IF(ISNA(VLOOKUP(B5,'NÖBV 2'!$J$3:$K$34,2,FALSE))=TRUE,0,VLOOKUP(B5,'NÖBV 2'!$J$3:$K$34,2,FALSE)),IF(ISNA(VLOOKUP(B5,'NÖBV 2'!$N$3:$O$34,2,FALSE))=TRUE,0,VLOOKUP(B5,'NÖBV 2'!$N$3:$O$34,2,FALSE))) -> 0 | N5: =MAX(IF(ISNA(VLOOKUP(B5,'NÖBV 3'!$B$3:$C$34,2,FALSE))=TRUE,0,VLOOKUP(B5,'NÖBV 3'!$B$3:$C$34,2,FALSE)),IF(ISNA(VLOOKUP(B5,'NÖBV 3'!$F$3:$G$34,2,FALSE))=TRUE,0,VLOOKUP(B5,'NÖBV 3'!$F$3:$G$34,2,FALSE)),IF(ISNA(VLOOKUP(B5,'NÖBV 3'!$J$3:$K$34,2,FALSE))=TRUE,0,VLOOKUP(B5,'NÖBV 3'!$J$3:$K$34,2,FALSE)),IF(ISNA(VLOOKUP(B5,'NÖBV 3'!$N$3:$O$34,2,FALSE))=TRUE,0,VLOOKUP(B5,'NÖBV 3'!$N$3:$O$34,2,FALSE))) -> 0 | O5: =MAX(IF(ISNA(VLOOKUP(B5,'Regioturnier 1'!$B$3:$C$34,2,FALSE))=TRUE,0,VLOOKUP(B5,'Regioturnier 1'!$B$3:$C$34,2,FALSE)),IF(ISNA(VLOOKUP(B5,'Regioturnier 1'!$F$3:$G$34,2,FALSE))=TRUE,0,VLOOKUP(B5,'Regioturnier 1'!$F$3:$G$34,2,FALSE)),IF(ISNA(VLOOKUP(B5,'Regioturnier 1'!$J$3:$K$34,2,FALSE))=TRUE,0,VLOOKUP(B5,'Regioturnier 1'!$J$3:$K$34,2,FALSE)),IF(ISNA(VLOOKUP(B5,'Regioturnier 1'!$N$3:$O$34,2,FALSE))=TRUE,0,VLOOKUP(B5,'Regioturnier 1'!$N$3:$O$34,2,FALSE)),IF(ISNA(VLOOKUP(B5,'Regioturnier 1'!$R$3:$S$34,2,FALSE))=TRUE,0,VLOOKUP(B5,'Regioturnier 1'!$R$3:$S$34,2,FALSE)), IF(ISNA(VLOOKUP(B5,'Regioturnier 1'!$V$3:$W$34,2,FALSE))=TRUE,0,VLOOKUP(B5,'Regioturnier 1'!$V$3:$W$34,2,FALSE)), IF(ISNA(VLOOKUP(B5,'Regioturnier 1'!$Z$3:$AA$34,2,FALSE))=TRUE,0,VLOOKUP(B5,'Regioturnier 1'!$Z$3:$AA$34,2,FALSE))) -> 210 | P5: =MAX(IF(ISNA(VLOOKUP(B5,'Regioturnier 2'!$B$3:$C$34,2,FALSE))=TRUE,0,VLOOKUP(B5,'Regioturnier 2'!$B$3:$C$34,2,FALSE)),IF(ISNA(VLOOKUP(B5,'Regioturnier 2'!$F$3:$G$34,2,FALSE))=TRUE,0,VLOOKUP(B5,'Regioturnier 2'!$F$3:$G$34,2,FALSE)),IF(ISNA(VLOOKUP(B5,'Regioturnier 2'!$J$3:$K$34,2,FALSE))=TRUE,0,VLOOKUP(B5,'Regioturnier 2'!$J$3:$K$34,2,FALSE)),IF(ISNA(VLOOKUP(B5,'Regioturnier 2'!$N$3:$O$34,2,FALSE))=TRUE,0,VLOOKUP(B5,'Regioturnier 2'!$N$3:$O$34,2,FALSE)),IF(ISNA(VLOOKUP(B5,'Regioturnier 2'!$R$3:$S$34,2,FALSE))=TRUE,0,VLOOKUP(B5,'Regioturnier 2'!$R$3:$S$34,2,FALSE)), IF(ISNA(VLOOKUP(B5,'Regioturnier 2'!$V$3:$W$34,2,FALSE))=TRUE,0,VLOOKUP(B5,'Regioturnier 2'!$V$3:$W$34,2,FALSE)), IF(ISNA(VLOOKUP(B5,'Regioturnier 2'!$Z$3:$AA$34,2,FALSE))=TRUE,0,VLOOKUP(B5,'Regioturnier 2'!$Z$3:$AA$34,2,FALSE))) -> 210 | Q5: =MAX(IF(ISNA(VLOOKUP(B5,'Regioturnier 3'!$B$3:$C$34,2,FALSE))=TRUE,0,VLOOKUP(B5,'Regioturnier 3'!$B$3:$C$34,2,FALSE)),IF(ISNA(VLOOKUP(B5,'Regioturnier 3'!$F$3:$G$34,2,FALSE))=TRUE,0,VLOOKUP(B5,'Regioturnier 3'!$F$3:$G$34,2,FALSE)),IF(ISNA(VLOOKUP(B5,'Regioturnier 3'!$J$3:$K$34,2,FALSE))=TRUE,0,VLOOKUP(B5,'Regioturnier 3'!$J$3:$K$34,2,FALSE)),IF(ISNA(VLOOKUP(B5,'Regioturnier 3'!$N$3:$O$34,2,FALSE))=TRUE,0,VLOOKUP(B5,'Regioturnier 3'!$N$3:$O$34,2,FALSE)),IF(ISNA(VLOOKUP(B5,'Regioturnier 3'!$R$3:$S$34,2,FALSE))=TRUE,0,VLOOKUP(B5,'Regioturnier 3'!$R$3:$S$34,2,FALSE)), IF(ISNA(VLOOKUP(B5,'Regioturnier 3'!$V$3:$W$34,2,FALSE))=TRUE,0,VLOOKUP(B5,'Regioturnier 3'!$V$3:$W$34,2,FALSE)), IF(ISNA(VLOOKUP(B5,'Regioturnier 3'!$Z$3:$AA$34,2,FALSE))=TRUE,0,VLOOKUP(B5,'Regioturnier 3'!$Z$3:$AA$34,2,FALSE))) -> 0 | R5: =0.5*INDEX($H5:$N5,MATCH(LARGE($H5:$N5,1),$H5:$N5,0))+0.3*INDEX($H5:$N5,MATCH(LARGE($H5:$N5,2),$H5:$N5,0))+0.2*INDEX($H5:$N5,MATCH(LARGE($H5:$N5,3),$H5:$N5,0)) -> 197.6 | S5: =0.6*INDEX(O5:Q5,MATCH(LARGE(O5:Q5,1),O5:Q5,0))+0.4*INDEX(O5:Q5,MATCH(LARGE(O5:Q5,2),O5:Q5,0))+0*INDEX(O5:Q5,MATCH(LARGE(O5:Q5,3),O5:Q5,0)) -> 210 | T5: =1*INDEX(R5:S5,MATCH(LARGE(R5:S5,1),R5:S5,0))+0*INDEX(R5:S5,MATCH(LARGE(R5:S5,2),R5:S5,0)) -> 210
A6: 5 | B6: Wenzel Tiapal | C6: ASV Pressbaum | D6: NÖBV | E6: M | F6: 207093 | G6: 2012 | H6: =MAX(IF(ISNA(VLOOKUP(B6,'WBV 1'!$B$3:$C$34,2,FALSE))=TRUE,0,VLOOKUP(B6,'WBV 1'!$B$3:$C$34,2,FALSE)),IF(ISNA(VLOOKUP(B6,'WBV 1'!$F$3:$G$34,2,FALSE))=TRUE,0,VLOOKUP(B6,'WBV 1'!$F$3:$G$34,2,FALSE)),IF(ISNA(VLOOKUP(B6,'WBV 1'!$J$3:$K$34,2,FALSE))=TRUE,0,VLOOKUP(B6,'WBV 1'!$J$3:$K$34,2,FALSE)),IF(ISNA(VLOOKUP(B6,'WBV 1'!$N$3:$O$34,2,FALSE))=TRUE,0,VLOOKUP(B6,'WBV 1'!$N$3:$O$34,2,FALSE))) -> 0 | I6: =MAX(IF(ISNA(VLOOKUP(B6,'WBV 2'!$B$3:$C$34,2,FALSE))=TRUE,0,VLOOKUP(B6,'WBV 2'!$B$3:$C$34,2,FALSE)),IF(ISNA(VLOOKUP(B6,'WBV 2'!$F$3:$G$34,2,FALSE))=TRUE,0,VLOOKUP(B6,'WBV 2'!$F$3:$G$34,2,FALSE)),IF(ISNA(VLOOKUP(B6,'WBV 2'!$J$3:$K$34,2,FALSE))=TRUE,0,VLOOKUP(B6,'WBV 2'!$J$3:$K$34,2,FALSE)),IF(ISNA(VLOOKUP(B6,'WBV 2'!$N$3:$O$34,2,FALSE))=TRUE,0,VLOOKUP(B6,'WBV 2'!$N$3:$O$34,2,FALSE))) -> 0 | J6: =MAX(IF(ISNA(VLOOKUP(B6,'WBV 3'!$B$3:$C$34,2,FALSE))=TRUE,0,VLOOKUP(B6,'WBV 3'!$B$3:$C$34,2,FALSE)),IF(ISNA(VLOOKUP(B6,'WBV 3'!$F$3:$G$34,2,FALSE))=TRUE,0,VLOOKUP(B6,'WBV 3'!$F$3:$G$34,2,FALSE)),IF(ISNA(VLOOKUP(B6,'WBV 3'!$J$3:$K$34,2,FALSE))=TRUE,0,VLOOKUP(B6,'WBV 3'!$J$3:$K$34,2,FALSE)),IF(ISNA(VLOOKUP(B6,'WBV 3'!$N$3:$O$34,2,FALSE))=TRUE,0,VLOOKUP(B6,'WBV 3'!$N$3:$O$34,2,FALSE))) -> 0 | K6: =MAX(IF(ISNA(VLOOKUP(B6,'WBV 4'!$B$3:$C$34,2,FALSE))=TRUE,0,VLOOKUP(B6,'WBV 4'!$B$3:$C$34,2,FALSE)),IF(ISNA(VLOOKUP(B6,'WBV 4'!$F$3:$G$34,2,FALSE))=TRUE,0,VLOOKUP(B6,'WBV 4'!$F$3:$G$34,2,FALSE)),IF(ISNA(VLOOKUP(B6,'WBV 4'!$J$3:$K$34,2,FALSE))=TRUE,0,VLOOKUP(B6,'WBV 4'!$J$3:$K$34,2,FALSE)),IF(ISNA(VLOOKUP(B6,'WBV 4'!$N$3:$O$34,2,FALSE))=TRUE,0,VLOOKUP(B6,'WBV 4'!$N$3:$O$34,2,FALSE))) -> 0 | L6: =MAX(IF(ISNA(VLOOKUP(B6,'NÖBV 1'!$B$3:$C$34,2,FALSE))=TRUE,0,VLOOKUP(B6,'NÖBV 1'!$B$3:$C$34,2,FALSE)),IF(ISNA(VLOOKUP(B6,'NÖBV 1'!$F$3:$G$34,2,FALSE))=TRUE,0,VLOOKUP(B6,'NÖBV 1'!$F$3:$G$34,2,FALSE)),IF(ISNA(VLOOKUP(B6,'NÖBV 1'!$J$3:$K$34,2,FALSE))=TRUE,0,VLOOKUP(B6,'NÖBV 1'!$J$3:$K$34,2,FALSE)),IF(ISNA(VLOOKUP(B6,'NÖBV 1'!$N$3:$O$34,2,FALSE))=TRUE,0,VLOOKUP(B6,'NÖBV 1'!$N$3:$O$34,2,FALSE))) -> 192 | M6: =MAX(IF(ISNA(VLOOKUP(B6,'NÖBV 2'!$B$3:$C$34,2,FALSE))=TRUE,0,VLOOKUP(B6,'NÖBV 2'!$B$3:$C$34,2,FALSE)),IF(ISNA(VLOOKUP(B6,'NÖBV 2'!$F$3:$G$34,2,FALSE))=TRUE,0,VLOOKUP(B6,'NÖBV 2'!$F$3:$G$34,2,FALSE)),IF(ISNA(VLOOKUP(B6,'NÖBV 2'!$J$3:$K$34,2,FALSE))=TRUE,0,VLOOKUP(B6,'NÖBV 2'!$J$3:$K$34,2,FALSE)),IF(ISNA(VLOOKUP(B6,'NÖBV 2'!$N$3:$O$34,2,FALSE))=TRUE,0,VLOOKUP(B6,'NÖBV 2'!$N$3:$O$34,2,FALSE))) -> 198 | N6: =MAX(IF(ISNA(VLOOKUP(B6,'NÖBV 3'!$B$3:$C$34,2,FALSE))=TRUE,0,VLOOKUP(B6,'NÖBV 3'!$B$3:$C$34,2,FALSE)),IF(ISNA(VLOOKUP(B6,'NÖBV 3'!$F$3:$G$34,2,FALSE))=TRUE,0,VLOOKUP(B6,'NÖBV 3'!$F$3:$G$34,2,FALSE)),IF(ISNA(VLOOKUP(B6,'NÖBV 3'!$J$3:$K$34,2,FALSE))=TRUE,0,VLOOKUP(B6,'NÖBV 3'!$J$3:$K$34,2,FALSE)),IF(ISNA(VLOOKUP(B6,'NÖBV 3'!$N$3:$O$34,2,FALSE))=TRUE,0,VLOOKUP(B6,'NÖBV 3'!$N$3:$O$34,2,FALSE))) -> 0 | O6: =MAX(IF(ISNA(VLOOKUP(B6,'Regioturnier 1'!$B$3:$C$34,2,FALSE))=TRUE,0,VLOOKUP(B6,'Regioturnier 1'!$B$3:$C$34,2,FALSE)),IF(ISNA(VLOOKUP(B6,'Regioturnier 1'!$F$3:$G$34,2,FALSE))=TRUE,0,VLOOKUP(B6,'Regioturnier 1'!$F$3:$G$34,2,FALSE)),IF(ISNA(VLOOKUP(B6,'Regioturnier 1'!$J$3:$K$34,2,FALSE))=TRUE,0,VLOOKUP(B6,'Regioturnier 1'!$J$3:$K$34,2,FALSE)),IF(ISNA(VLOOKUP(B6,'Regioturnier 1'!$N$3:$O$34,2,FALSE))=TRUE,0,VLOOKUP(B6,'Regioturnier 1'!$N$3:$O$34,2,FALSE)),IF(ISNA(VLOOKUP(B6,'Regioturnier 1'!$R$3:$S$34,2,FALSE))=TRUE,0,VLOOKUP(B6,'Regioturnier 1'!$R$3:$S$34,2,FALSE)), IF(ISNA(VLOOKUP(B6,'Regioturnier 1'!$V$3:$W$34,2,FALSE))=TRUE,0,VLOOKUP(B6,'Regioturnier 1'!$V$3:$W$34,2,FALSE)), IF(ISNA(VLOOKUP(B6,'Regioturnier 1'!$Z$3:$AA$34,2,FALSE))=TRUE,0,VLOOKUP(B6,'Regioturnier 1'!$Z$3:$AA$34,2,FALSE))) -> 206 | P6: =MAX(IF(ISNA(VLOOKUP(B6,'Regioturnier 2'!$B$3:$C$34,2,FALSE))=TRUE,0,VLOOKUP(B6,'Regioturnier 2'!$B$3:$C$34,2,FALSE)),IF(ISNA(VLOOKUP(B6,'Regioturnier 2'!$F$3:$G$34,2,FALSE))=TRUE,0,VLOOKUP(B6,'Regioturnier 2'!$F$3:$G$34,2,FALSE)),IF(ISNA(VLOOKUP(B6,'Regioturnier 2'!$J$3:$K$34,2,FALSE))=TRUE,0,VLOOKUP(B6,'Regioturnier 2'!$J$3:$K$34,2,FALSE)),IF(ISNA(VLOOKUP(B6,'Regioturnier 2'!$N$3:$O$34,2,FALSE))=TRUE,0,VLOOKUP(B6,'Regioturnier 2'!$N$3:$O$34,2,FALSE)),IF(ISNA(VLOOKUP(B6,'Regioturnier 2'!$R$3:$S$34,2,FALSE))=TRUE,0,VLOOKUP(B6,'Regioturnier 2'!$R$3:$S$34,2,FALSE)), IF(ISNA(VLOOKUP(B6,'Regioturnier 2'!$V$3:$W$34,2,FALSE))=TRUE,0,VLOOKUP(B6,'Regioturnier 2'!$V$3:$W$34,2,FALSE)), IF(ISNA(VLOOKUP(B6,'Regioturnier 2'!$Z$3:$AA$34,2,FALSE))=TRUE,0,VLOOKUP(B6,'Regioturnier 2'!$Z$3:$AA$34,2,FALSE))) -> 208 | Q6: =MAX(IF(ISNA(VLOOKUP(B6,'Regioturnier 3'!$B$3:$C$34,2,FALSE))=TRUE,0,VLOOKUP(B6,'Regioturnier 3'!$B$3:$C$34,2,FALSE)),IF(ISNA(VLOOKUP(B6,'Regioturnier 3'!$F$3:$G$34,2,FALSE))=TRUE,0,VLOOKUP(B6,'Regioturnier 3'!$F$3:$G$34,2,FALSE)),IF(ISNA(VLOOKUP(B6,'Regioturnier 3'!$J$3:$K$34,2,FALSE))=TRUE,0,VLOOKUP(B6,'Regioturnier 3'!$J$3:$K$34,2,FALSE)),IF(ISNA(VLOOKUP(B6,'Regioturnier 3'!$N$3:$O$34,2,FALSE))=TRUE,0,VLOOKUP(B6,'Regioturnier 3'!$N$3:$O$34,2,FALSE)),IF(ISNA(VLOOKUP(B6,'Regioturnier 3'!$R$3:$S$34,2,FALSE))=TRUE,0,VLOOKUP(B6,'Regioturnier 3'!$R$3:$S$34,2,FALSE)), IF(ISNA(VLOOKUP(B6,'Regioturnier 3'!$V$3:$W$34,2,FALSE))=TRUE,0,VLOOKUP(B6,'Regioturnier 3'!$V$3:$W$34,2,FALSE)), IF(ISNA(VLOOKUP(B6,'Regioturnier 3'!$Z$3:$AA$34,2,FALSE))=TRUE,0,VLOOKUP(B6,'Regioturnier 3'!$Z$3:$AA$34,2,FALSE))) -> 0 | R6: =0.5*INDEX($H6:$N6,MATCH(LARGE($H6:$N6,1),$H6:$N6,0))+0.3*INDEX($H6:$N6,MATCH(LARGE($H6:$N6,2),$H6:$N6,0))+0.2*INDEX($H6:$N6,MATCH(LARGE($H6:$N6,3),$H6:$N6,0)) -> 156.6 | S6: =0.6*INDEX(O6:Q6,MATCH(LARGE(O6:Q6,1),O6:Q6,0))+0.4*INDEX(O6:Q6,MATCH(LARGE(O6:Q6,2),O6:Q6,0))+0*INDEX(O6:Q6,MATCH(LARGE(O6:Q6,3),O6:Q6,0)) -> 207.2 | T6: =1*INDEX(R6:S6,MATCH(LARGE(R6:S6,1),R6:S6,0))+0*INDEX(R6:S6,MATCH(LARGE(R6:S6,2),R6:S6,0)) -> 207.2
A7: 6 | B7: Samuel Nemeskal | C7: VRC | D7: WBV | E7: M | F7: 111568 | G7: 2010 | H7: =MAX(IF(ISNA(VLOOKUP(B7,'WBV 1'!$B$3:$C$34,2,FALSE))=TRUE,0,VLOOKUP(B7,'WBV 1'!$B$3:$C$34,2,FALSE)),IF(ISNA(VLOOKUP(B7,'WBV 1'!$F$3:$G$34,2,FALSE))=TRUE,0,VLOOKUP(B7,'WBV 1'!$F$3:$G$34,2,FALSE)),IF(ISNA(VLOOKUP(B7,'WBV 1'!$J$3:$K$34,2,FALSE))=TRUE,0,VLOOKUP(B7,'WBV 1'!$J$3:$K$34,2,FALSE)),IF(ISNA(VLOOKUP(B7,'WBV 1'!$N$3:$O$34,2,FALSE))=TRUE,0,VLOOKUP(B7,'WBV 1'!$N$3:$O$34,2,FALSE))) -> 0 | I7: =MAX(IF(ISNA(VLOOKUP(B7,'WBV 2'!$B$3:$C$34,2,FALSE))=TRUE,0,VLOOKUP(B7,'WBV 2'!$B$3:$C$34,2,FALSE)),IF(ISNA(VLOOKUP(B7,'WBV 2'!$F$3:$G$34,2,FALSE))=TRUE,0,VLOOKUP(B7,'WBV 2'!$F$3:$G$34,2,FALSE)),IF(ISNA(VLOOKUP(B7,'WBV 2'!$J$3:$K$34,2,FALSE))=TRUE,0,VLOOKUP(B7,'WBV 2'!$J$3:$K$34,2,FALSE)),IF(ISNA(VLOOKUP(B7,'WBV 2'!$N$3:$O$34,2,FALSE))=TRUE,0,VLOOKUP(B7,'WBV 2'!$N$3:$O$34,2,FALSE))) -> 0 | J7: =MAX(IF(ISNA(VLOOKUP(B7,'WBV 3'!$B$3:$C$34,2,FALSE))=TRUE,0,VLOOKUP(B7,'WBV 3'!$B$3:$C$34,2,FALSE)),IF(ISNA(VLOOKUP(B7,'WBV 3'!$F$3:$G$34,2,FALSE))=TRUE,0,VLOOKUP(B7,'WBV 3'!$F$3:$G$34,2,FALSE)),IF(ISNA(VLOOKUP(B7,'WBV 3'!$J$3:$K$34,2,FALSE))=TRUE,0,VLOOKUP(B7,'WBV 3'!$J$3:$K$34,2,FALSE)),IF(ISNA(VLOOKUP(B7,'WBV 3'!$N$3:$O$34,2,FALSE))=TRUE,0,VLOOKUP(B7,'WBV 3'!$N$3:$O$34,2,FALSE))) -> 0 | K7: =MAX(IF(ISNA(VLOOKUP(B7,'WBV 4'!$B$3:$C$34,2,FALSE))=TRUE,0,VLOOKUP(B7,'WBV 4'!$B$3:$C$34,2,FALSE)),IF(ISNA(VLOOKUP(B7,'WBV 4'!$F$3:$G$34,2,FALSE))=TRUE,0,VLOOKUP(B7,'WBV 4'!$F$3:$G$34,2,FALSE)),IF(ISNA(VLOOKUP(B7,'WBV 4'!$J$3:$K$34,2,FALSE))=TRUE,0,VLOOKUP(B7,'WBV 4'!$J$3:$K$34,2,FALSE)),IF(ISNA(VLOOKUP(B7,'WBV 4'!$N$3:$O$34,2,FALSE))=TRUE,0,VLOOKUP(B7,'WBV 4'!$N$3:$O$34,2,FALSE))) -> 0 | L7: =MAX(IF(ISNA(VLOOKUP(B7,'NÖBV 1'!$B$3:$C$34,2,FALSE))=TRUE,0,VLOOKUP(B7,'NÖBV 1'!$B$3:$C$34,2,FALSE)),IF(ISNA(VLOOKUP(B7,'NÖBV 1'!$F$3:$G$34,2,FALSE))=TRUE,0,VLOOKUP(B7,'NÖBV 1'!$F$3:$G$34,2,FALSE)),IF(ISNA(VLOOKUP(B7,'NÖBV 1'!$J$3:$K$34,2,FALSE))=TRUE,0,VLOOKUP(B7,'NÖBV 1'!$J$3:$K$34,2,FALSE)),IF(ISNA(VLOOKUP(B7,'NÖBV 1'!$N$3:$O$34,2,FALSE))=TRUE,0,VLOOKUP(B7,'NÖBV 1'!$N$3:$O$34,2,FALSE))) -> 0 | M7: =MAX(IF(ISNA(VLOOKUP(B7,'NÖBV 2'!$B$3:$C$34,2,FALSE))=TRUE,0,VLOOKUP(B7,'NÖBV 2'!$B$3:$C$34,2,FALSE)),IF(ISNA(VLOOKUP(B7,'NÖBV 2'!$F$3:$G$34,2,FALSE))=TRUE,0,VLOOKUP(B7,'NÖBV 2'!$F$3:$G$34,2,FALSE)),IF(ISNA(VLOOKUP(B7,'NÖBV 2'!$J$3:$K$34,2,FALSE))=TRUE,0,VLOOKUP(B7,'NÖBV 2'!$J$3:$K$34,2,FALSE)),IF(ISNA(VLOOKUP(B7,'NÖBV 2'!$N$3:$O$34,2,FALSE))=TRUE,0,VLOOKUP(B7,'NÖBV 2'!$N$3:$O$34,2,FALSE))) -> 0 | N7: =MAX(IF(ISNA(VLOOKUP(B7,'NÖBV 3'!$B$3:$C$34,2,FALSE))=TRUE,0,VLOOKUP(B7,'NÖBV 3'!$B$3:$C$34,2,FALSE)),IF(ISNA(VLOOKUP(B7,'NÖBV 3'!$F$3:$G$34,2,FALSE))=TRUE,0,VLOOKUP(B7,'NÖBV 3'!$F$3:$G$34,2,FALSE)),IF(ISNA(VLOOKUP(B7,'NÖBV 3'!$J$3:$K$34,2,FALSE))=TRUE,0,VLOOKUP(B7,'NÖBV 3'!$J$3:$K$34,2,FALSE)),IF(ISNA(VLOOKUP(B7,'NÖBV 3'!$N$3:$O$34,2,FALSE))=TRUE,0,VLOOKUP(B7,'NÖBV 3'!$N$3:$O$34,2,FALSE))) -> 0 | O7: =MAX(IF(ISNA(VLOOKUP(B7,'Regioturnier 1'!$B$3:$C$34,2,FALSE))=TRUE,0,VLOOKUP(B7,'Regioturnier 1'!$B$3:$C$34,2,FALSE)),IF(ISNA(VLOOKUP(B7,'Regioturnier 1'!$F$3:$G$34,2,FALSE))=TRUE,0,VLOOKUP(B7,'Regioturnier 1'!$F$3:$G$34,2,FALSE)),IF(ISNA(VLOOKUP(B7,'Regioturnier 1'!$J$3:$K$34,2,FALSE))=TRUE,0,VLOOKUP(B7,'Regioturnier 1'!$J$3:$K$34,2,FALSE)),IF(ISNA(VLOOKUP(B7,'Regioturnier 1'!$N$3:$O$34,2,FALSE))=TRUE,0,VLOOKUP(B7,'Regioturnier 1'!$N$3:$O$34,2,FALSE)),IF(ISNA(VLOOKUP(B7,'Regioturnier 1'!$R$3:$S$34,2,FALSE))=TRUE,0,VLOOKUP(B7,'Regioturnier 1'!$R$3:$S$34,2,FALSE)), IF(ISNA(VLOOKUP(B7,'Regioturnier 1'!$V$3:$W$34,2,FALSE))=TRUE,0,VLOOKUP(B7,'Regioturnier 1'!$V$3:$W$34,2,FALSE)), IF(ISNA(VLOOKUP(B7,'Regioturnier 1'!$Z$3:$AA$34,2,FALSE))=TRUE,0,VLOOKUP(B7,'Regioturnier 1'!$Z$3:$AA$34,2,FALSE))) -> 200 | P7: =MAX(IF(ISNA(VLOOKUP(B7,'Regioturnier 2'!$B$3:$C$34,2,FALSE))=TRUE,0,VLOOKUP(B7,'Regioturnier 2'!$B$3:$C$34,2,FALSE)),IF(ISNA(VLOOKUP(B7,'Regioturnier 2'!$F$3:$G$34,2,FALSE))=TRUE,0,VLOOKUP(B7,'Regioturnier 2'!$F$3:$G$34,2,FALSE)),IF(ISNA(VLOOKUP(B7,'Regioturnier 2'!$J$3:$K$34,2,FALSE))=TRUE,0,VLOOKUP(B7,'Regioturnier 2'!$J$3:$K$34,2,FALSE)),IF(ISNA(VLOOKUP(B7,'Regioturnier 2'!$N$3:$O$34,2,FALSE))=TRUE,0,VLOOKUP(B7,'Regioturnier 2'!$N$3:$O$34,2,FALSE)),IF(ISNA(VLOOKUP(B7,'Regioturnier 2'!$R$3:$S$34,2,FALSE))=TRUE,0,VLOOKUP(B7,'Regioturnier 2'!$R$3:$S$34,2,FALSE)), IF(ISNA(VLOOKUP(B7,'Regioturnier 2'!$V$3:$W$34,2,FALSE))=TRUE,0,VLOOKUP(B7,'Regioturnier 2'!$V$3:$W$34,2,FALSE)), IF(ISNA(VLOOKUP(B7,'Regioturnier 2'!$Z$3:$AA$34,2,FALSE))=TRUE,0,VLOOKUP(B7,'Regioturnier 2'!$Z$3:$AA$34,2,FALSE))) -> 207 | Q7: =MAX(IF(ISNA(VLOOKUP(B7,'Regioturnier 3'!$B$3:$C$34,2,FALSE))=TRUE,0,VLOOKUP(B7,'Regioturnier 3'!$B$3:$C$34,2,FALSE)),IF(ISNA(VLOOKUP(B7,'Regioturnier 3'!$F$3:$G$34,2,FALSE))=TRUE,0,VLOOKUP(B7,'Regioturnier 3'!$F$3:$G$34,2,FALSE)),IF(ISNA(VLOOKUP(B7,'Regioturnier 3'!$J$3:$K$34,2,FALSE))=TRUE,0,VLOOKUP(B7,'Regioturnier 3'!$J$3:$K$34,2,FALSE)),IF(ISNA(VLOOKUP(B7,'Regioturnier 3'!$N$3:$O$34,2,FALSE))=TRUE,0,VLOOKUP(B7,'Regioturnier 3'!$N$3:$O$34,2,FALSE)),IF(ISNA(VLOOKUP(B7,'Regioturnier 3'!$R$3:$S$34,2,FALSE))=TRUE,0,VLOOKUP(B7,'Regioturnier 3'!$R$3:$S$34,2,FALSE)), IF(ISNA(VLOOKUP(B7,'Regioturnier 3'!$V$3:$W$34,2,FALSE))=TRUE,0,VLOOKUP(B7,'Regioturnier 3'!$V$3:$W$34,2,FALSE)), IF(ISNA(VLOOKUP(B7,'Regioturnier 3'!$Z$3:$AA$34,2,FALSE))=TRUE,0,VLOOKUP(B7,'Regioturnier 3'!$Z$3:$AA$34,2,FALSE))) -> 0 | R7: =0.5*INDEX($H7:$N7,MATCH(LARGE($H7:$N7,1),$H7:$N7,0))+0.3*INDEX($H7:$N7,MATCH(LARGE($H7:$N7,2),$H7:$N7,0))+0.2*INDEX($H7:$N7,MATCH(LARGE($H7:$N7,3),$H7:$N7,0)) -> 0 | S7: =0.6*INDEX(O7:Q7,MATCH(LARGE(O7:Q7,1),O7:Q7,0))+0.4*INDEX(O7:Q7,MATCH(LARGE(O7:Q7,2),O7:Q7,0))+0*INDEX(O7:Q7,MATCH(LARGE(O7:Q7,3),O7:Q7,0)) -> 204.2 | T7: =1*INDEX(R7:S7,MATCH(LARGE(R7:S7,1),R7:S7,0))+0*INDEX(R7:S7,MATCH(LARGE(R7:S7,2),R7:S7,0)) -> 204.2
A8: 7 | B8: Philipp Grebien | C8: WBH WIEN | D8: WBV | E8: M | F8: 110047 | G8: 2014 | H8: =MAX(IF(ISNA(VLOOKUP(B8,'WBV 1'!$B$3:$C$34,2,FALSE))=TRUE,0,VLOOKUP(B8,'WBV 1'!$B$3:$C$34,2,FALSE)),IF(ISNA(VLOOKUP(B8,'WBV 1'!$F$3:$G$34,2,FALSE))=TRUE,0,VLOOKUP(B8,'WBV 1'!$F$3:$G$34,2,FALSE)),IF(ISNA(VLOOKUP(B8,'WBV 1'!$J$3:$K$34,2,FALSE))=TRUE,0,VLOOKUP(B8,'WBV 1'!$J$3:$K$34,2,FALSE)),IF(ISNA(VLOOKUP(B8,'WBV 1'!$N$3:$O$34,2,FALSE))=TRUE,0,VLOOKUP(B8,'WBV 1'!$N$3:$O$34,2,FALSE))) -> 0 | I8: =MAX(IF(ISNA(VLOOKUP(B8,'WBV 2'!$B$3:$C$34,2,FALSE))=TRUE,0,VLOOKUP(B8,'WBV 2'!$B$3:$C$34,2,FALSE)),IF(ISNA(VLOOKUP(B8,'WBV 2'!$F$3:$G$34,2,FALSE))=TRUE,0,VLOOKUP(B8,'WBV 2'!$F$3:$G$34,2,FALSE)),IF(ISNA(VLOOKUP(B8,'WBV 2'!$J$3:$K$34,2,FALSE))=TRUE,0,VLOOKUP(B8,'WBV 2'!$J$3:$K$34,2,FALSE)),IF(ISNA(VLOOKUP(B8,'WBV 2'!$N$3:$O$34,2,FALSE))=TRUE,0,VLOOKUP(B8,'WBV 2'!$N$3:$O$34,2,FALSE))) -> 0 | J8: =MAX(IF(ISNA(VLOOKUP(B8,'WBV 3'!$B$3:$C$34,2,FALSE))=TRUE,0,VLOOKUP(B8,'WBV 3'!$B$3:$C$34,2,FALSE)),IF(ISNA(VLOOKUP(B8,'WBV 3'!$F$3:$G$34,2,FALSE))=TRUE,0,VLOOKUP(B8,'WBV 3'!$F$3:$G$34,2,FALSE)),IF(ISNA(VLOOKUP(B8,'WBV 3'!$J$3:$K$34,2,FALSE))=TRUE,0,VLOOKUP(B8,'WBV 3'!$J$3:$K$34,2,FALSE)),IF(ISNA(VLOOKUP(B8,'WBV 3'!$N$3:$O$34,2,FALSE))=TRUE,0,VLOOKUP(B8,'WBV 3'!$N$3:$O$34,2,FALSE))) -> 196 | K8: =MAX(IF(ISNA(VLOOKUP(B8,'WBV 4'!$B$3:$C$34,2,FALSE))=TRUE,0,VLOOKUP(B8,'WBV 4'!$B$3:$C$34,2,FALSE)),IF(ISNA(VLOOKUP(B8,'WBV 4'!$F$3:$G$34,2,FALSE))=TRUE,0,VLOOKUP(B8,'WBV 4'!$F$3:$G$34,2,FALSE)),IF(ISNA(VLOOKUP(B8,'WBV 4'!$J$3:$K$34,2,FALSE))=TRUE,0,VLOOKUP(B8,'WBV 4'!$J$3:$K$34,2,FALSE)),IF(ISNA(VLOOKUP(B8,'WBV 4'!$N$3:$O$34,2,FALSE))=TRUE,0,VLOOKUP(B8,'WBV 4'!$N$3:$O$34,2,FALSE))) -> 0 | L8: =MAX(IF(ISNA(VLOOKUP(B8,'NÖBV 1'!$B$3:$C$34,2,FALSE))=TRUE,0,VLOOKUP(B8,'NÖBV 1'!$B$3:$C$34,2,FALSE)),IF(ISNA(VLOOKUP(B8,'NÖBV 1'!$F$3:$G$34,2,FALSE))=TRUE,0,VLOOKUP(B8,'NÖBV 1'!$F$3:$G$34,2,FALSE)),IF(ISNA(VLOOKUP(B8,'NÖBV 1'!$J$3:$K$34,2,FALSE))=TRUE,0,VLOOKUP(B8,'NÖBV 1'!$J$3:$K$34,2,FALSE)),IF(ISNA(VLOOKUP(B8,'NÖBV 1'!$N$3:$O$34,2,FALSE))=TRUE,0,VLOOKUP(B8,'NÖBV 1'!$N$3:$O$34,2,FALSE))) -> 0 | M8: =MAX(IF(ISNA(VLOOKUP(B8,'NÖBV 2'!$B$3:$C$34,2,FALSE))=TRUE,0,VLOOKUP(B8,'NÖBV 2'!$B$3:$C$34,2,FALSE)),IF(ISNA(VLOOKUP(B8,'NÖBV 2'!$F$3:$G$34,2,FALSE))=TRUE,0,VLOOKUP(B8,'NÖBV 2'!$F$3:$G$34,2,FALSE)),IF(ISNA(VLOOKUP(B8,'NÖBV 2'!$J$3:$K$34,2,FALSE))=TRUE,0,VLOOKUP(B8,'NÖBV 2'!$J$3:$K$34,2,FALSE)),IF(ISNA(VLOOKUP(B8,'NÖBV 2'!$N$3:$O$34,2,FALSE))=TRUE,0,VLOOKUP(B8,'NÖBV 2'!$N$3:$O$34,2,FALSE))) -> 0 | N8: =MAX(IF(ISNA(VLOOKUP(B8,'NÖBV 3'!$B$3:$C$34,2,FALSE))=TRUE,0,VLOOKUP(B8,'NÖBV 3'!$B$3:$C$34,2,FALSE)),IF(ISNA(VLOOKUP(B8,'NÖBV 3'!$F$3:$G$34,2,FALSE))=TRUE,0,VLOOKUP(B8,'NÖBV 3'!$F$3:$G$34,2,FALSE)),IF(ISNA(VLOOKUP(B8,'NÖBV 3'!$J$3:$K$34,2,FALSE))=TRUE,0,VLOOKUP(B8,'NÖBV 3'!$J$3:$K$34,2,FALSE)),IF(ISNA(VLOOKUP(B8,'NÖBV 3'!$N$3:$O$34,2,FALSE))=TRUE,0,VLOOKUP(B8,'NÖBV 3'!$N$3:$O$34,2,FALSE))) -> 0 | O8: =MAX(IF(ISNA(VLOOKUP(B8,'Regioturnier 1'!$B$3:$C$34,2,FALSE))=TRUE,0,VLOOKUP(B8,'Regioturnier 1'!$B$3:$C$34,2,FALSE)),IF(ISNA(VLOOKUP(B8,'Regioturnier 1'!$F$3:$G$34,2,FALSE))=TRUE,0,VLOOKUP(B8,'Regioturnier 1'!$F$3:$G$34,2,FALSE)),IF(ISNA(VLOOKUP(B8,'Regioturnier 1'!$J$3:$K$34,2,FALSE))=TRUE,0,VLOOKUP(B8,'Regioturnier 1'!$J$3:$K$34,2,FALSE)),IF(ISNA(VLOOKUP(B8,'Regioturnier 1'!$N$3:$O$34,2,FALSE))=TRUE,0,VLOOKUP(B8,'Regioturnier 1'!$N$3:$O$34,2,FALSE)),IF(ISNA(VLOOKUP(B8,'Regioturnier 1'!$R$3:$S$34,2,FALSE))=TRUE,0,VLOOKUP(B8,'Regioturnier 1'!$R$3:$S$34,2,FALSE)), IF(ISNA(VLOOKUP(B8,'Regioturnier 1'!$V$3:$W$34,2,FALSE))=TRUE,0,VLOOKUP(B8,'Regioturnier 1'!$V$3:$W$34,2,FALSE)), IF(ISNA(VLOOKUP(B8,'Regioturnier 1'!$Z$3:$AA$34,2,FALSE))=TRUE,0,VLOOKUP(B8,'Regioturnier 1'!$Z$3:$AA$34,2,FALSE))) -> 201 | P8: =MAX(IF(ISNA(VLOOKUP(B8,'Regioturnier 2'!$B$3:$C$34,2,FALSE))=TRUE,0,VLOOKUP(B8,'Regioturnier 2'!$B$3:$C$34,2,FALSE)),IF(ISNA(VLOOKUP(B8,'Regioturnier 2'!$F$3:$G$34,2,FALSE))=TRUE,0,VLOOKUP(B8,'Regioturnier 2'!$F$3:$G$34,2,FALSE)),IF(ISNA(VLOOKUP(B8,'Regioturnier 2'!$J$3:$K$34,2,FALSE))=TRUE,0,VLOOKUP(B8,'Regioturnier 2'!$J$3:$K$34,2,FALSE)),IF(ISNA(VLOOKUP(B8,'Regioturnier 2'!$N$3:$O$34,2,FALSE))=TRUE,0,VLOOKUP(B8,'Regioturnier 2'!$N$3:$O$34,2,FALSE)),IF(ISNA(VLOOKUP(B8,'Regioturnier 2'!$R$3:$S$34,2,FALSE))=TRUE,0,VLOOKUP(B8,'Regioturnier 2'!$R$3:$S$34,2,FALSE)), IF(ISNA(VLOOKUP(B8,'Regioturnier 2'!$V$3:$W$34,2,FALSE))=TRUE,0,VLOOKUP(B8,'Regioturnier 2'!$V$3:$W$34,2,FALSE)), IF(ISNA(VLOOKUP(B8,'Regioturnier 2'!$Z$3:$AA$34,2,FALSE))=TRUE,0,VLOOKUP(B8,'Regioturnier 2'!$Z$3:$AA$34,2,FALSE))) -> 205 | Q8: =MAX(IF(ISNA(VLOOKUP(B8,'Regioturnier 3'!$B$3:$C$34,2,FALSE))=TRUE,0,VLOOKUP(B8,'Regioturnier 3'!$B$3:$C$34,2,FALSE)),IF(ISNA(VLOOKUP(B8,'Regioturnier 3'!$F$3:$G$34,2,FALSE))=TRUE,0,VLOOKUP(B8,'Regioturnier 3'!$F$3:$G$34,2,FALSE)),IF(ISNA(VLOOKUP(B8,'Regioturnier 3'!$J$3:$K$34,2,FALSE))=TRUE,0,VLOOKUP(B8,'Regioturnier 3'!$J$3:$K$34,2,FALSE)),IF(ISNA(VLOOKUP(B8,'Regioturnier 3'!$N$3:$O$34,2,FALSE))=TRUE,0,VLOOKUP(B8,'Regioturnier 3'!$N$3:$O$34,2,FALSE)),IF(ISNA(VLOOKUP(B8,'Regioturnier 3'!$R$3:$S$34,2,FALSE))=TRUE,0,VLOOKUP(B8,'Regioturnier 3'!$R$3:$S$34,2,FALSE)), IF(ISNA(VLOOKUP(B8,'Regioturnier 3'!$V$3:$W$34,2,FALSE))=TRUE,0,VLOOKUP(B8,'Regioturnier 3'!$V$3:$W$34,2,FALSE)), IF(ISNA(VLOOKUP(B8,'Regioturnier 3'!$Z$3:$AA$34,2,FALSE))=TRUE,0,VLOOKUP(B8,'Regioturnier 3'!$Z$3:$AA$34,2,FALSE))) -> 0 | R8: =0.5*INDEX($H8:$N8,MATCH(LARGE($H8:$N8,1),$H8:$N8,0))+0.3*INDEX($H8:$N8,MATCH(LARGE($H8:$N8,2),$H8:$N8,0))+0.2*INDEX($H8:$N8,MATCH(LARGE($H8:$N8,3),$H8:$N8,0)) -> 98 | S8: =0.6*INDEX(O8:Q8,MATCH(LARGE(O8:Q8,1),O8:Q8,0))+0.4*INDEX(O8:Q8,MATCH(LARGE(O8:Q8,2),O8:Q8,0))+0*INDEX(O8:Q8,MATCH(LARGE(O8:Q8,3),O8:Q8,0)) -> 203.4 | T8: =1*INDEX(R8:S8,MATCH(LARGE(R8:S8,1),R8:S8,0))+0*INDEX(R8:S8,MATCH(LARGE(R8:S8,2),R8:S8,0)) -> 203.4
A9: 8 | B9: Valentin Schefcik | C9: Badminton Mödling | D9: NÖBV | E9: M | F9: 26473 | G9: 2010 | H9: =MAX(IF(ISNA(VLOOKUP(B9,'WBV 1'!$B$3:$C$34,2,FALSE))=TRUE,0,VLOOKUP(B9,'WBV 1'!$B$3:$C$34,2,FALSE)),IF(ISNA(VLOOKUP(B9,'WBV 1'!$F$3:$G$34,2,FALSE))=TRUE,0,VLOOKUP(B9,'WBV 1'!$F$3:$G$34,2,FALSE)),IF(ISNA(VLOOKUP(B9,'WBV 1'!$J$3:$K$34,2,FALSE))=TRUE,0,VLOOKUP(B9,'WBV 1'!$J$3:$K$34,2,FALSE)),IF(ISNA(VLOOKUP(B9,'WBV 1'!$N$3:$O$34,2,FALSE))=TRUE,0,VLOOKUP(B9,'WBV 1'!$N$3:$O$34,2,FALSE))) -> 0 | I9: =MAX(IF(ISNA(VLOOKUP(B9,'WBV 2'!$B$3:$C$34,2,FALSE))=TRUE,0,VLOOKUP(B9,'WBV 2'!$B$3:$C$34,2,FALSE)),IF(ISNA(VLOOKUP(B9,'WBV 2'!$F$3:$G$34,2,FALSE))=TRUE,0,VLOOKUP(B9,'WBV 2'!$F$3:$G$34,2,FALSE)),IF(ISNA(VLOOKUP(B9,'WBV 2'!$J$3:$K$34,2,FALSE))=TRUE,0,VLOOKUP(B9,'WBV 2'!$J$3:$K$34,2,FALSE)),IF(ISNA(VLOOKUP(B9,'WBV 2'!$N$3:$O$34,2,FALSE))=TRUE,0,VLOOKUP(B9,'WBV 2'!$N$3:$O$34,2,FALSE))) -> 0 | J9: =MAX(IF(ISNA(VLOOKUP(B9,'WBV 3'!$B$3:$C$34,2,FALSE))=TRUE,0,VLOOKUP(B9,'WBV 3'!$B$3:$C$34,2,FALSE)),IF(ISNA(VLOOKUP(B9,'WBV 3'!$F$3:$G$34,2,FALSE))=TRUE,0,VLOOKUP(B9,'WBV 3'!$F$3:$G$34,2,FALSE)),IF(ISNA(VLOOKUP(B9,'WBV 3'!$J$3:$K$34,2,FALSE))=TRUE,0,VLOOKUP(B9,'WBV 3'!$J$3:$K$34,2,FALSE)),IF(ISNA(VLOOKUP(B9,'WBV 3'!$N$3:$O$34,2,FALSE))=TRUE,0,VLOOKUP(B9,'WBV 3'!$N$3:$O$34,2,FALSE))) -> 0 | K9: =MAX(IF(ISNA(VLOOKUP(B9,'WBV 4'!$B$3:$C$34,2,FALSE))=TRUE,0,VLOOKUP(B9,'WBV 4'!$B$3:$C$34,2,FALSE)),IF(ISNA(VLOOKUP(B9,'WBV 4'!$F$3:$G$34,2,FALSE))=TRUE,0,VLOOKUP(B9,'WBV 4'!$F$3:$G$34,2,FALSE)),IF(ISNA(VLOOKUP(B9,'WBV 4'!$J$3:$K$34,2,FALSE))=TRUE,0,VLOOKUP(B9,'WBV 4'!$J$3:$K$34,2,FALSE)),IF(ISNA(VLOOKUP(B9,'WBV 4'!$N$3:$O$34,2,FALSE))=TRUE,0,VLOOKUP(B9,'WBV 4'!$N$3:$O$34,2,FALSE))) -> 0 | L9: =MAX(IF(ISNA(VLOOKUP(B9,'NÖBV 1'!$B$3:$C$34,2,FALSE))=TRUE,0,VLOOKUP(B9,'NÖBV 1'!$B$3:$C$34,2,FALSE)),IF(ISNA(VLOOKUP(B9,'NÖBV 1'!$F$3:$G$34,2,FALSE))=TRUE,0,VLOOKUP(B9,'NÖBV 1'!$F$3:$G$34,2,FALSE)),IF(ISNA(VLOOKUP(B9,'NÖBV 1'!$J$3:$K$34,2,FALSE))=TRUE,0,VLOOKUP(B9,'NÖBV 1'!$J$3:$K$34,2,FALSE)),IF(ISNA(VLOOKUP(B9,'NÖBV 1'!$N$3:$O$34,2,FALSE))=TRUE,0,VLOOKUP(B9,'NÖBV 1'!$N$3:$O$34,2,FALSE))) -> 0 | M9: =MAX(IF(ISNA(VLOOKUP(B9,'NÖBV 2'!$B$3:$C$34,2,FALSE))=TRUE,0,VLOOKUP(B9,'NÖBV 2'!$B$3:$C$34,2,FALSE)),IF(ISNA(VLOOKUP(B9,'NÖBV 2'!$F$3:$G$34,2,FALSE))=TRUE,0,VLOOKUP(B9,'NÖBV 2'!$F$3:$G$34,2,FALSE)),IF(ISNA(VLOOKUP(B9,'NÖBV 2'!$J$3:$K$34,2,FALSE))=TRUE,0,VLOOKUP(B9,'NÖBV 2'!$J$3:$K$34,2,FALSE)),IF(ISNA(VLOOKUP(B9,'NÖBV 2'!$N$3:$O$34,2,FALSE))=TRUE,0,VLOOKUP(B9,'NÖBV 2'!$N$3:$O$34,2,FALSE))) -> 192 | N9: =MAX(IF(ISNA(VLOOKUP(B9,'NÖBV 3'!$B$3:$C$34,2,FALSE))=TRUE,0,VLOOKUP(B9,'NÖBV 3'!$B$3:$C$34,2,FALSE)),IF(ISNA(VLOOKUP(B9,'NÖBV 3'!$F$3:$G$34,2,FALSE))=TRUE,0,VLOOKUP(B9,'NÖBV 3'!$F$3:$G$34,2,FALSE)),IF(ISNA(VLOOKUP(B9,'NÖBV 3'!$J$3:$K$34,2,FALSE))=TRUE,0,VLOOKUP(B9,'NÖBV 3'!$J$3:$K$34,2,FALSE)),IF(ISNA(VLOOKUP(B9,'NÖBV 3'!$N$3:$O$34,2,FALSE))=TRUE,0,VLOOKUP(B9,'NÖBV 3'!$N$3:$O$34,2,FALSE))) -> 200 | O9: =MAX(IF(ISNA(VLOOKUP(B9,'Regioturnier 1'!$B$3:$C$34,2,FALSE))=TRUE,0,VLOOKUP(B9,'Regioturnier 1'!$B$3:$C$34,2,FALSE)),IF(ISNA(VLOOKUP(B9,'Regioturnier 1'!$F$3:$G$34,2,FALSE))=TRUE,0,VLOOKUP(B9,'Regioturnier 1'!$F$3:$G$34,2,FALSE)),IF(ISNA(VLOOKUP(B9,'Regioturnier 1'!$J$3:$K$34,2,FALSE))=TRUE,0,VLOOKUP(B9,'Regioturnier 1'!$J$3:$K$34,2,FALSE)),IF(ISNA(VLOOKUP(B9,'Regioturnier 1'!$N$3:$O$34,2,FALSE))=TRUE,0,VLOOKUP(B9,'Regioturnier 1'!$N$3:$O$34,2,FALSE)),IF(ISNA(VLOOKUP(B9,'Regioturnier 1'!$R$3:$S$34,2,FALSE))=TRUE,0,VLOOKUP(B9,'Regioturnier 1'!$R$3:$S$34,2,FALSE)), IF(ISNA(VLOOKUP(B9,'Regioturnier 1'!$V$3:$W$34,2,FALSE))=TRUE,0,VLOOKUP(B9,'Regioturnier 1'!$V$3:$W$34,2,FALSE)), IF(ISNA(VLOOKUP(B9,'Regioturnier 1'!$Z$3:$AA$34,2,FALSE))=TRUE,0,VLOOKUP(B9,'Regioturnier 1'!$Z$3:$AA$34,2,FALSE))) -> 202 | P9: =MAX(IF(ISNA(VLOOKUP(B9,'Regioturnier 2'!$B$3:$C$34,2,FALSE))=TRUE,0,VLOOKUP(B9,'Regioturnier 2'!$B$3:$C$34,2,FALSE)),IF(ISNA(VLOOKUP(B9,'Regioturnier 2'!$F$3:$G$34,2,FALSE))=TRUE,0,VLOOKUP(B9,'Regioturnier 2'!$F$3:$G$34,2,FALSE)),IF(ISNA(VLOOKUP(B9,'Regioturnier 2'!$J$3:$K$34,2,FALSE))=TRUE,0,VLOOKUP(B9,'Regioturnier 2'!$J$3:$K$34,2,FALSE)),IF(ISNA(VLOOKUP(B9,'Regioturnier 2'!$N$3:$O$34,2,FALSE))=TRUE,0,VLOOKUP(B9,'Regioturnier 2'!$N$3:$O$34,2,FALSE)),IF(ISNA(VLOOKUP(B9,'Regioturnier 2'!$R$3:$S$34,2,FALSE))=TRUE,0,VLOOKUP(B9,'Regioturnier 2'!$R$3:$S$34,2,FALSE)), IF(ISNA(VLOOKUP(B9,'Regioturnier 2'!$V$3:$W$34,2,FALSE))=TRUE,0,VLOOKUP(B9,'Regioturnier 2'!$V$3:$W$34,2,FALSE)), IF(ISNA(VLOOKUP(B9,'Regioturnier 2'!$Z$3:$AA$34,2,FALSE))=TRUE,0,VLOOKUP(B9,'Regioturnier 2'!$Z$3:$AA$34,2,FALSE))) -> 204 | Q9: =MAX(IF(ISNA(VLOOKUP(B9,'Regioturnier 3'!$B$3:$C$34,2,FALSE))=TRUE,0,VLOOKUP(B9,'Regioturnier 3'!$B$3:$C$34,2,FALSE)),IF(ISNA(VLOOKUP(B9,'Regioturnier 3'!$F$3:$G$34,2,FALSE))=TRUE,0,VLOOKUP(B9,'Regioturnier 3'!$F$3:$G$34,2,FALSE)),IF(ISNA(VLOOKUP(B9,'Regioturnier 3'!$J$3:$K$34,2,FALSE))=TRUE,0,VLOOKUP(B9,'Regioturnier 3'!$J$3:$K$34,2,FALSE)),IF(ISNA(VLOOKUP(B9,'Regioturnier 3'!$N$3:$O$34,2,FALSE))=TRUE,0,VLOOKUP(B9,'Regioturnier 3'!$N$3:$O$34,2,FALSE)),IF(ISNA(VLOOKUP(B9,'Regioturnier 3'!$R$3:$S$34,2,FALSE))=TRUE,0,VLOOKUP(B9,'Regioturnier 3'!$R$3:$S$34,2,FALSE)), IF(ISNA(VLOOKUP(B9,'Regioturnier 3'!$V$3:$W$34,2,FALSE))=TRUE,0,VLOOKUP(B9,'Regioturnier 3'!$V$3:$W$34,2,FALSE)), IF(ISNA(VLOOKUP(B9,'Regioturnier 3'!$Z$3:$AA$34,2,FALSE))=TRUE,0,VLOOKUP(B9,'Regioturnier 3'!$Z$3:$AA$34,2,FALSE))) -> 0 | R9: =0.5*INDEX($H9:$N9,MATCH(LARGE($H9:$N9,1),$H9:$N9,0))+0.3*INDEX($H9:$N9,MATCH(LARGE($H9:$N9,2),$H9:$N9,0))+0.2*INDEX($H9:$N9,MATCH(LARGE($H9:$N9,3),$H9:$N9,0)) -> 157.6 | S9: =0.6*INDEX(O9:Q9,MATCH(LARGE(O9:Q9,1),O9:Q9,0))+0.4*INDEX(O9:Q9,MATCH(LARGE(O9:Q9,2),O9:Q9,0))+0*INDEX(O9:Q9,MATCH(LARGE(O9:Q9,3),O9:Q9,0)) -> 203.2 | T9: =1*INDEX(R9:S9,MATCH(LARGE(R9:S9,1),R9:S9,0))+0*INDEX(R9:S9,MATCH(LARGE(R9:S9,2),R9:S9,0)) -> 203.2
A10: 9 | B10: Laura Schindler | C10: WBH WIEN | D10: WBV | E10: W | F10: 108588 | G10: 2010 | H10: =MAX(IF(ISNA(VLOOKUP(B10,'WBV 1'!$B$3:$C$34,2,FALSE))=TRUE,0,VLOOKUP(B10,'WBV 1'!$B$3:$C$34,2,FALSE)),IF(ISNA(VLOOKUP(B10,'WBV 1'!$F$3:$G$34,2,FALSE))=TRUE,0,VLOOKUP(B10,'WBV 1'!$F$3:$G$34,2,FALSE)),IF(ISNA(VLOOKUP(B10,'WBV 1'!$J$3:$K$34,2,FALSE))=TRUE,0,VLOOKUP(B10,'WBV 1'!$J$3:$K$34,2,FALSE)),IF(ISNA(VLOOKUP(B10,'WBV 1'!$N$3:$O$34,2,FALSE))=TRUE,0,VLOOKUP(B10,'WBV 1'!$N$3:$O$34,2,FALSE))) -> 0 | I10: =MAX(IF(ISNA(VLOOKUP(B10,'WBV 2'!$B$3:$C$34,2,FALSE))=TRUE,0,VLOOKUP(B10,'WBV 2'!$B$3:$C$34,2,FALSE)),IF(ISNA(VLOOKUP(B10,'WBV 2'!$F$3:$G$34,2,FALSE))=TRUE,0,VLOOKUP(B10,'WBV 2'!$F$3:$G$34,2,FALSE)),IF(ISNA(VLOOKUP(B10,'WBV 2'!$J$3:$K$34,2,FALSE))=TRUE,0,VLOOKUP(B10,'WBV 2'!$J$3:$K$34,2,FALSE)),IF(ISNA(VLOOKUP(B10,'WBV 2'!$N$3:$O$34,2,FALSE))=TRUE,0,VLOOKUP(B10,'WBV 2'!$N$3:$O$34,2,FALSE))) -> 183 | J10: =MAX(IF(ISNA(VLOOKUP(B10,'WBV 3'!$B$3:$C$34,2,FALSE))=TRUE,0,VLOOKUP(B10,'WBV 3'!$B$3:$C$34,2,FALSE)),IF(ISNA(VLOOKUP(B10,'WBV 3'!$F$3:$G$34,2,FALSE))=TRUE,0,VLOOKUP(B10,'WBV 3'!$F$3:$G$34,2,FALSE)),IF(ISNA(VLOOKUP(B10,'WBV 3'!$J$3:$K$34,2,FALSE))=TRUE,0,VLOOKUP(B10,'WBV 3'!$J$3:$K$34,2,FALSE)),IF(ISNA(VLOOKUP(B10,'WBV 3'!$N$3:$O$34,2,FALSE))=TRUE,0,VLOOKUP(B10,'WBV 3'!$N$3:$O$34,2,FALSE))) -> 189 | K10: =MAX(IF(ISNA(VLOOKUP(B10,'WBV 4'!$B$3:$C$34,2,FALSE))=TRUE,0,VLOOKUP(B10,'WBV 4'!$B$3:$C$34,2,FALSE)),IF(ISNA(VLOOKUP(B10,'WBV 4'!$F$3:$G$34,2,FALSE))=TRUE,0,VLOOKUP(B10,'WBV 4'!$F$3:$G$34,2,FALSE)),IF(ISNA(VLOOKUP(B10,'WBV 4'!$J$3:$K$34,2,FALSE))=TRUE,0,VLOOKUP(B10,'WBV 4'!$J$3:$K$34,2,FALSE)),IF(ISNA(VLOOKUP(B10,'WBV 4'!$N$3:$O$34,2,FALSE))=TRUE,0,VLOOKUP(B10,'WBV 4'!$N$3:$O$34,2,FALSE))) -> 0 | L10: =MAX(IF(ISNA(VLOOKUP(B10,'NÖBV 1'!$B$3:$C$34,2,FALSE))=TRUE,0,VLOOKUP(B10,'NÖBV 1'!$B$3:$C$34,2,FALSE)),IF(ISNA(VLOOKUP(B10,'NÖBV 1'!$F$3:$G$34,2,FALSE))=TRUE,0,VLOOKUP(B10,'NÖBV 1'!$F$3:$G$34,2,FALSE)),IF(ISNA(VLOOKUP(B10,'NÖBV 1'!$J$3:$K$34,2,FALSE))=TRUE,0,VLOOKUP(B10,'NÖBV 1'!$J$3:$K$34,2,FALSE)),IF(ISNA(VLOOKUP(B10,'NÖBV 1'!$N$3:$O$34,2,FALSE))=TRUE,0,VLOOKUP(B10,'NÖBV 1'!$N$3:$O$34,2,FALSE))) -> 0 | M10: =MAX(IF(ISNA(VLOOKUP(B10,'NÖBV 2'!$B$3:$C$34,2,FALSE))=TRUE,0,VLOOKUP(B10,'NÖBV 2'!$B$3:$C$34,2,FALSE)),IF(ISNA(VLOOKUP(B10,'NÖBV 2'!$F$3:$G$34,2,FALSE))=TRUE,0,VLOOKUP(B10,'NÖBV 2'!$F$3:$G$34,2,FALSE)),IF(ISNA(VLOOKUP(B10,'NÖBV 2'!$J$3:$K$34,2,FALSE))=TRUE,0,VLOOKUP(B10,'NÖBV 2'!$J$3:$K$34,2,FALSE)),IF(ISNA(VLOOKUP(B10,'NÖBV 2'!$N$3:$O$34,2,FALSE))=TRUE,0,VLOOKUP(B10,'NÖBV 2'!$N$3:$O$34,2,FALSE))) -> 0 | N10: =MAX(IF(ISNA(VLOOKUP(B10,'NÖBV 3'!$B$3:$C$34,2,FALSE))=TRUE,0,VLOOKUP(B10,'NÖBV 3'!$B$3:$C$34,2,FALSE)),IF(ISNA(VLOOKUP(B10,'NÖBV 3'!$F$3:$G$34,2,FALSE))=TRUE,0,VLOOKUP(B10,'NÖBV 3'!$F$3:$G$34,2,FALSE)),IF(ISNA(VLOOKUP(B10,'NÖBV 3'!$J$3:$K$34,2,FALSE))=TRUE,0,VLOOKUP(B10,'NÖBV 3'!$J$3:$K$34,2,FALSE)),IF(ISNA(VLOOKUP(B10,'NÖBV 3'!$N$3:$O$34,2,FALSE))=TRUE,0,VLOOKUP(B10,'NÖBV 3'!$N$3:$O$34,2,FALSE))) -> 0 | O10: =MAX(IF(ISNA(VLOOKUP(B10,'Regioturnier 1'!$B$3:$C$34,2,FALSE))=TRUE,0,VLOOKUP(B10,'Regioturnier 1'!$B$3:$C$34,2,FALSE)),IF(ISNA(VLOOKUP(B10,'Regioturnier 1'!$F$3:$G$34,2,FALSE))=TRUE,0,VLOOKUP(B10,'Regioturnier 1'!$F$3:$G$34,2,FALSE)),IF(ISNA(VLOOKUP(B10,'Regioturnier 1'!$J$3:$K$34,2,FALSE))=TRUE,0,VLOOKUP(B10,'Regioturnier 1'!$J$3:$K$34,2,FALSE)),IF(ISNA(VLOOKUP(B10,'Regioturnier 1'!$N$3:$O$34,2,FALSE))=TRUE,0,VLOOKUP(B10,'Regioturnier 1'!$N$3:$O$34,2,FALSE)),IF(ISNA(VLOOKUP(B10,'Regioturnier 1'!$R$3:$S$34,2,FALSE))=TRUE,0,VLOOKUP(B10,'Regioturnier 1'!$R$3:$S$34,2,FALSE)), IF(ISNA(VLOOKUP(B10,'Regioturnier 1'!$V$3:$W$34,2,FALSE))=TRUE,0,VLOOKUP(B10,'Regioturnier 1'!$V$3:$W$34,2,FALSE)), IF(ISNA(VLOOKUP(B10,'Regioturnier 1'!$Z$3:$AA$34,2,FALSE))=TRUE,0,VLOOKUP(B10,'Regioturnier 1'!$Z$3:$AA$34,2,FALSE))) -> 200 | P10: =MAX(IF(ISNA(VLOOKUP(B10,'Regioturnier 2'!$B$3:$C$34,2,FALSE))=TRUE,0,VLOOKUP(B10,'Regioturnier 2'!$B$3:$C$34,2,FALSE)),IF(ISNA(VLOOKUP(B10,'Regioturnier 2'!$F$3:$G$34,2,FALSE))=TRUE,0,VLOOKUP(B10,'Regioturnier 2'!$F$3:$G$34,2,FALSE)),IF(ISNA(VLOOKUP(B10,'Regioturnier 2'!$J$3:$K$34,2,FALSE))=TRUE,0,VLOOKUP(B10,'Regioturnier 2'!$J$3:$K$34,2,FALSE)),IF(ISNA(VLOOKUP(B10,'Regioturnier 2'!$N$3:$O$34,2,FALSE))=TRUE,0,VLOOKUP(B10,'Regioturnier 2'!$N$3:$O$34,2,FALSE)),IF(ISNA(VLOOKUP(B10,'Regioturnier 2'!$R$3:$S$34,2,FALSE))=TRUE,0,VLOOKUP(B10,'Regioturnier 2'!$R$3:$S$34,2,FALSE)), IF(ISNA(VLOOKUP(B10,'Regioturnier 2'!$V$3:$W$34,2,FALSE))=TRUE,0,VLOOKUP(B10,'Regioturnier 2'!$V$3:$W$34,2,FALSE)), IF(ISNA(VLOOKUP(B10,'Regioturnier 2'!$Z$3:$AA$34,2,FALSE))=TRUE,0,VLOOKUP(B10,'Regioturnier 2'!$Z$3:$AA$34,2,FALSE))) -> 195 | Q10: =MAX(IF(ISNA(VLOOKUP(B10,'Regioturnier 3'!$B$3:$C$34,2,FALSE))=TRUE,0,VLOOKUP(B10,'Regioturnier 3'!$B$3:$C$34,2,FALSE)),IF(ISNA(VLOOKUP(B10,'Regioturnier 3'!$F$3:$G$34,2,FALSE))=TRUE,0,VLOOKUP(B10,'Regioturnier 3'!$F$3:$G$34,2,FALSE)),IF(ISNA(VLOOKUP(B10,'Regioturnier 3'!$J$3:$K$34,2,FALSE))=TRUE,0,VLOOKUP(B10,'Regioturnier 3'!$J$3:$K$34,2,FALSE)),IF(ISNA(VLOOKUP(B10,'Regioturnier 3'!$N$3:$O$34,2,FALSE))=TRUE,0,VLOOKUP(B10,'Regioturnier 3'!$N$3:$O$34,2,FALSE)),IF(ISNA(VLOOKUP(B10,'Regioturnier 3'!$R$3:$S$34,2,FALSE))=TRUE,0,VLOOKUP(B10,'Regioturnier 3'!$R$3:$S$34,2,FALSE)), IF(ISNA(VLOOKUP(B10,'Regioturnier 3'!$V$3:$W$34,2,FALSE))=TRUE,0,VLOOKUP(B10,'Regioturnier 3'!$V$3:$W$34,2,FALSE)), IF(ISNA(VLOOKUP(B10,'Regioturnier 3'!$Z$3:$AA$34,2,FALSE))=TRUE,0,VLOOKUP(B10,'Regioturnier 3'!$Z$3:$AA$34,2,FALSE))) -> 0 | R10: =0.5*INDEX($H10:$N10,MATCH(LARGE($H10:$N10,1),$H10:$N10,0))+0.3*INDEX($H10:$N10,MATCH(LARGE($H10:$N10,2),$H10:$N10,0))+0.2*INDEX($H10:$N10,MATCH(LARGE($H10:$N10,3),$H10:$N10,0)) -> 149.4 | S10: =0.6*INDEX(O10:Q10,MATCH(LARGE(O10:Q10,1),O10:Q10,0))+0.4*INDEX(O10:Q10,MATCH(LARGE(O10:Q10,2),O10:Q10,0))+0*INDEX(O10:Q10,MATCH(LARGE(O10:Q10,3),O10:Q10,0)) -> 198 | T10: =1*INDEX(R10:S10,MATCH(LARGE(R10:S10,1),R10:S10,0))+0*INDEX(R10:S10,MATCH(LARGE(R10:S10,2),R10:S10,0)) -> 198
A11: 10 | B11: Felix Sztatecsny | C11: ASV Pressbaum | D11: NÖBV | E11: M | F11: 207993 | G11: 2013 | H11: =MAX(IF(ISNA(VLOOKUP(B11,'WBV 1'!$B$3:$C$34,2,FALSE))=TRUE,0,VLOOKUP(B11,'WBV 1'!$B$3:$C$34,2,FALSE)),IF(ISNA(VLOOKUP(B11,'WBV 1'!$F$3:$G$34,2,FALSE))=TRUE,0,VLOOKUP(B11,'WBV 1'!$F$3:$G$34,2,FALSE)),IF(ISNA(VLOOKUP(B11,'WBV 1'!$J$3:$K$34,2,FALSE))=TRUE,0,VLOOKUP(B11,'WBV 1'!$J$3:$K$34,2,FALSE)),IF(ISNA(VLOOKUP(B11,'WBV 1'!$N$3:$O$34,2,FALSE))=TRUE,0,VLOOKUP(B11,'WBV 1'!$N$3:$O$34,2,FALSE))) -> 0 | I11: =MAX(IF(ISNA(VLOOKUP(B11,'WBV 2'!$B$3:$C$34,2,FALSE))=TRUE,0,VLOOKUP(B11,'WBV 2'!$B$3:$C$34,2,FALSE)),IF(ISNA(VLOOKUP(B11,'WBV 2'!$F$3:$G$34,2,FALSE))=TRUE,0,VLOOKUP(B11,'WBV 2'!$F$3:$G$34,2,FALSE)),IF(ISNA(VLOOKUP(B11,'WBV 2'!$J$3:$K$34,2,FALSE))=TRUE,0,VLOOKUP(B11,'WBV 2'!$J$3:$K$34,2,FALSE)),IF(ISNA(VLOOKUP(B11,'WBV 2'!$N$3:$O$34,2,FALSE))=TRUE,0,VLOOKUP(B11,'WBV 2'!$N$3:$O$34,2,FALSE))) -> 0 | J11: =MAX(IF(ISNA(VLOOKUP(B11,'WBV 3'!$B$3:$C$34,2,FALSE))=TRUE,0,VLOOKUP(B11,'WBV 3'!$B$3:$C$34,2,FALSE)),IF(ISNA(VLOOKUP(B11,'WBV 3'!$F$3:$G$34,2,FALSE))=TRUE,0,VLOOKUP(B11,'WBV 3'!$F$3:$G$34,2,FALSE)),IF(ISNA(VLOOKUP(B11,'WBV 3'!$J$3:$K$34,2,FALSE))=TRUE,0,VLOOKUP(B11,'WBV 3'!$J$3:$K$34,2,FALSE)),IF(ISNA(VLOOKUP(B11,'WBV 3'!$N$3:$O$34,2,FALSE))=TRUE,0,VLOOKUP(B11,'WBV 3'!$N$3:$O$34,2,FALSE))) -> 0 | K11: =MAX(IF(ISNA(VLOOKUP(B11,'WBV 4'!$B$3:$C$34,2,FALSE))=TRUE,0,VLOOKUP(B11,'WBV 4'!$B$3:$C$34,2,FALSE)),IF(ISNA(VLOOKUP(B11,'WBV 4'!$F$3:$G$34,2,FALSE))=TRUE,0,VLOOKUP(B11,'WBV 4'!$F$3:$G$34,2,FALSE)),IF(ISNA(VLOOKUP(B11,'WBV 4'!$J$3:$K$34,2,FALSE))=TRUE,0,VLOOKUP(B11,'WBV 4'!$J$3:$K$34,2,FALSE)),IF(ISNA(VLOOKUP(B11,'WBV 4'!$N$3:$O$34,2,FALSE))=TRUE,0,VLOOKUP(B11,'WBV 4'!$N$3:$O$34,2,FALSE))) -> 0 | L11: =MAX(IF(ISNA(VLOOKUP(B11,'NÖBV 1'!$B$3:$C$34,2,FALSE))=TRUE,0,VLOOKUP(B11,'NÖBV 1'!$B$3:$C$34,2,FALSE)),IF(ISNA(VLOOKUP(B11,'NÖBV 1'!$F$3:$G$34,2,FALSE))=TRUE,0,VLOOKUP(B11,'NÖBV 1'!$F$3:$G$34,2,FALSE)),IF(ISNA(VLOOKUP(B11,'NÖBV 1'!$J$3:$K$34,2,FALSE))=TRUE,0,VLOOKUP(B11,'NÖBV 1'!$J$3:$K$34,2,FALSE)),IF(ISNA(VLOOKUP(B11,'NÖBV 1'!$N$3:$O$34,2,FALSE))=TRUE,0,VLOOKUP(B11,'NÖBV 1'!$N$3:$O$34,2,FALSE))) -> 183 | M11: =MAX(IF(ISNA(VLOOKUP(B11,'NÖBV 2'!$B$3:$C$34,2,FALSE))=TRUE,0,VLOOKUP(B11,'NÖBV 2'!$B$3:$C$34,2,FALSE)),IF(ISNA(VLOOKUP(B11,'NÖBV 2'!$F$3:$G$34,2,FALSE))=TRUE,0,VLOOKUP(B11,'NÖBV 2'!$F$3:$G$34,2,FALSE)),IF(ISNA(VLOOKUP(B11,'NÖBV 2'!$J$3:$K$34,2,FALSE))=TRUE,0,VLOOKUP(B11,'NÖBV 2'!$J$3:$K$34,2,FALSE)),IF(ISNA(VLOOKUP(B11,'NÖBV 2'!$N$3:$O$34,2,FALSE))=TRUE,0,VLOOKUP(B11,'NÖBV 2'!$N$3:$O$34,2,FALSE))) -> 0 | N11: =MAX(IF(ISNA(VLOOKUP(B11,'NÖBV 3'!$B$3:$C$34,2,FALSE))=TRUE,0,VLOOKUP(B11,'NÖBV 3'!$B$3:$C$34,2,FALSE)),IF(ISNA(VLOOKUP(B11,'NÖBV 3'!$F$3:$G$34,2,FALSE))=TRUE,0,VLOOKUP(B11,'NÖBV 3'!$F$3:$G$34,2,FALSE)),IF(ISNA(VLOOKUP(B11,'NÖBV 3'!$J$3:$K$34,2,FALSE))=TRUE,0,VLOOKUP(B11,'NÖBV 3'!$J$3:$K$34,2,FALSE)),IF(ISNA(VLOOKUP(B11,'NÖBV 3'!$N$3:$O$34,2,FALSE))=TRUE,0,VLOOKUP(B11,'NÖBV 3'!$N$3:$O$34,2,FALSE))) -> 0 | O11: =MAX(IF(ISNA(VLOOKUP(B11,'Regioturnier 1'!$B$3:$C$34,2,FALSE))=TRUE,0,VLOOKUP(B11,'Regioturnier 1'!$B$3:$C$34,2,FALSE)),IF(ISNA(VLOOKUP(B11,'Regioturnier 1'!$F$3:$G$34,2,FALSE))=TRUE,0,VLOOKUP(B11,'Regioturnier 1'!$F$3:$G$34,2,FALSE)),IF(ISNA(VLOOKUP(B11,'Regioturnier 1'!$J$3:$K$34,2,FALSE))=TRUE,0,VLOOKUP(B11,'Regioturnier 1'!$J$3:$K$34,2,FALSE)),IF(ISNA(VLOOKUP(B11,'Regioturnier 1'!$N$3:$O$34,2,FALSE))=TRUE,0,VLOOKUP(B11,'Regioturnier 1'!$N$3:$O$34,2,FALSE)),IF(ISNA(VLOOKUP(B11,'Regioturnier 1'!$R$3:$S$34,2,FALSE))=TRUE,0,VLOOKUP(B11,'Regioturnier 1'!$R$3:$S$34,2,FALSE)), IF(ISNA(VLOOKUP(B11,'Regioturnier 1'!$V$3:$W$34,2,FALSE))=TRUE,0,VLOOKUP(B11,'Regioturnier 1'!$V$3:$W$34,2,FALSE)), IF(ISNA(VLOOKUP(B11,'Regioturnier 1'!$Z$3:$AA$34,2,FALSE))=TRUE,0,VLOOKUP(B11,'Regioturnier 1'!$Z$3:$AA$34,2,FALSE))) -> 191 | P11: =MAX(IF(ISNA(VLOOKUP(B11,'Regioturnier 2'!$B$3:$C$34,2,FALSE))=TRUE,0,VLOOKUP(B11,'Regioturnier 2'!$B$3:$C$34,2,FALSE)),IF(ISNA(VLOOKUP(B11,'Regioturnier 2'!$F$3:$G$34,2,FALSE))=TRUE,0,VLOOKUP(B11,'Regioturnier 2'!$F$3:$G$34,2,FALSE)),IF(ISNA(VLOOKUP(B11,'Regioturnier 2'!$J$3:$K$34,2,FALSE))=TRUE,0,VLOOKUP(B11,'Regioturnier 2'!$J$3:$K$34,2,FALSE)),IF(ISNA(VLOOKUP(B11,'Regioturnier 2'!$N$3:$O$34,2,FALSE))=TRUE,0,VLOOKUP(B11,'Regioturnier 2'!$N$3:$O$34,2,FALSE)),IF(ISNA(VLOOKUP(B11,'Regioturnier 2'!$R$3:$S$34,2,FALSE))=TRUE,0,VLOOKUP(B11,'Regioturnier 2'!$R$3:$S$34,2,FALSE)), IF(ISNA(VLOOKUP(B11,'Regioturnier 2'!$V$3:$W$34,2,FALSE))=TRUE,0,VLOOKUP(B11,'Regioturnier 2'!$V$3:$W$34,2,FALSE)), IF(ISNA(VLOOKUP(B11,'Regioturnier 2'!$Z$3:$AA$34,2,FALSE))=TRUE,0,VLOOKUP(B11,'Regioturnier 2'!$Z$3:$AA$34,2,FALSE))) -> 201 | Q11: =MAX(IF(ISNA(VLOOKUP(B11,'Regioturnier 3'!$B$3:$C$34,2,FALSE))=TRUE,0,VLOOKUP(B11,'Regioturnier 3'!$B$3:$C$34,2,FALSE)),IF(ISNA(VLOOKUP(B11,'Regioturnier 3'!$F$3:$G$34,2,FALSE))=TRUE,0,VLOOKUP(B11,'Regioturnier 3'!$F$3:$G$34,2,FALSE)),IF(ISNA(VLOOKUP(B11,'Regioturnier 3'!$J$3:$K$34,2,FALSE))=TRUE,0,VLOOKUP(B11,'Regioturnier 3'!$J$3:$K$34,2,FALSE)),IF(ISNA(VLOOKUP(B11,'Regioturnier 3'!$N$3:$O$34,2,FALSE))=TRUE,0,VLOOKUP(B11,'Regioturnier 3'!$N$3:$O$34,2,FALSE)),IF(ISNA(VLOOKUP(B11,'Regioturnier 3'!$R$3:$S$34,2,FALSE))=TRUE,0,VLOOKUP(B11,'Regioturnier 3'!$R$3:$S$34,2,FALSE)), IF(ISNA(VLOOKUP(B11,'Regioturnier 3'!$V$3:$W$34,2,FALSE))=TRUE,0,VLOOKUP(B11,'Regioturnier 3'!$V$3:$W$34,2,FALSE)), IF(ISNA(VLOOKUP(B11,'Regioturnier 3'!$Z$3:$AA$34,2,FALSE))=TRUE,0,VLOOKUP(B11,'Regioturnier 3'!$Z$3:$AA$34,2,FALSE))) -> 0 | R11: =0.5*INDEX($H11:$N11,MATCH(LARGE($H11:$N11,1),$H11:$N11,0))+0.3*INDEX($H11:$N11,MATCH(LARGE($H11:$N11,2),$H11:$N11,0))+0.2*INDEX($H11:$N11,MATCH(LARGE($H11:$N11,3),$H11:$N11,0)) -> 91.5 | S11: =0.6*INDEX(O11:Q11,MATCH(LARGE(O11:Q11,1),O11:Q11,0))+0.4*INDEX(O11:Q11,MATCH(LARGE(O11:Q11,2),O11:Q11,0))+0*INDEX(O11:Q11,MATCH(LARGE(O11:Q11,3),O11:Q11,0)) -> 197 | T11: =1*INDEX(R11:S11,MATCH(LARGE(R11:S11,1),R11:S11,0))+0*INDEX(R11:S11,MATCH(LARGE(R11:S11,2),R11:S11,0)) -> 197
